Workbook
Name CU?: 'JV Waterfall'!$A$5
Name Equity_Share_GP: 'JV Waterfall'!$C$8
Name Equity_Share_LP: 'JV Waterfall'!$C$9
Name Preferred_Return: 'JV Waterfall'!$E$14
Name SF: Budget!$E$5
Name Total_Equity: 'JV Waterfall'!$D$10

Sheet Budget
B2: =D2 -> 1500 Boston Post Road, Darien | D2: 1500 Boston Post Road, Darien | H2: Sources & Uses Summary | P2: =D2 -> 1500 Boston Post Road, Darien | T2: Leasing Commission Calculation
B3: Development Budget Notes | D3: Acquisition Budget | E3: Current Cost | F3: Cost/SF | H3: Total Capitalization (Sources) | I3: Amount | J3: $ PSF | L3: Total Project Cost (Uses) | M3: Amount | N3: $ PSF | P3: Project Capitalization | U3: =1 -> 1 | V3: =U3+1 -> 2 | W3: =V3+1 -> 3 | X3: =W3+1 -> 4 | Y3: =X3+1 -> 5 | Z3: =Y3+1 -> 6 | AA3: =Z3+1 -> 7 | AB3: =AA3+1 -> 8 | AC3: =AB3+1 -> 9 | ... AL3: =AK3+1 -> 18
B5: Per Offering Memorandum | D5: Building Sq. ft. | E5: 18754 | H5: =H23 -> Permanent Loan @ 64.25% LTC | I5: =I23 -> 6550000 | J5: =+I5/SF -> 349.25882 | L5: =D8 -> Occupied Building | M5: =E8 -> 9700000 | N5: =+M5/SF -> 517.22299 | P5: Total Capitalization | Q5: =E31 -> 10395210 | R5: =Q5/SF -> 554.29296 | T5: Year Ending | U5: 45107 | V5: =EOMONTH(U5,12) -> 45473 | W5: =EOMONTH(V5,12) -> 45838 | X5: =EOMONTH(W5,12) -> 46203 | Y5: =EOMONTH(X5,12) -> 46568 | Z5: =EOMONTH(Y5,12) -> 46934 | AA5: =EOMONTH(Z5,12) -> 47299 | AB5: =EOMONTH(AA5,12) -> 47664 | AC5: =EOMONTH(AB5,12) -> 48029 | ... AL5: =EOMONTH(AK5,12) -> 51317
H6: =H24 -> Equity Contribution @ 35.75% LTC | I6: =I24 -> 3551440.2 | J6: =+I6/SF -> 189.36975 | L6: =D9 -> Acquisition & Development Fee | M6: =E9 -> 200000 | N6: =+M6/SF -> 10.664392 | P6: =P24 -> Permanent Loan @ 64.25% LTC | Q6: =Q24 -> 6550000 | R6: =+Q6/$E$5 -> 349.25882
D7: Site Acquisition Costs | H7: Addition Equity Contribution | I7: =Q26+Q38 -> 293770 | J7: =+I7/SF -> 15.664392 | L7: =D26 -> Tenant Capital Reimbursement | M7: =E26 -> 93770 | N7: =+M7/SF -> 5 | P7: =P25 -> Equity Contribution @ 35.75% LTC | Q7: =Q25 -> 3551440.2 | R7: =+Q7/$E$5 -> 189.36975 | T7: Rental Rate | U7: =F33 -> 35.436907 | V7: =U7 -> 35.436907 | W7: =V7*1.02 -> 36.145645 | X7: =W7*1.02 -> 36.868558 | Y7: =X7*1.02 -> 37.605929 | Z7: =Y7*1.02 -> 38.358048 | AA7: =Z7*1.02 -> 39.125209 | AB7: =AA7*1.02 -> 39.907713 | AC7: =AB7*1.02 -> 40.705867 | AD7: =AC7*1.02 -> 41.519985 | ... AL7: =AK7*1.02 -> 48.64728
B8: Per Letter of Intent Dated 2.28.23 | D8: Occupied Building | E8: 9700000 | F8: =E8/$E$5 -> 517.22299 | G8: =E33/E8 -> 0.06851379 | L8: =D10 -> Lender Rent Escrow | M8: =E10 -> 68000 | N8: =+M8/SF -> 3.6258931 | P8: Additional Equity Contribution | Q8: =Q26 -> 93770 | R8: =+Q8/$E$5 -> 5 | T8: Existing Lease Obligations | U8: =F33 -> 35.436907 | V8: =U8 -> 35.436907 | W8: =V8 -> 35.436907 | X8: =W8 -> 35.436907 | Y8: =X8 -> 35.436907 | Z8: =Y8 -> 35.436907 | AA8: =Z8*1.1 -> 38.980598 | AB8: =AA8 -> 38.980598 | AC8: 0 | AD8: 0 | AE8: 0 | AF8: 0 | AG8: 0 | AH8: 0 | AI8: 0 | AJ8: 0 | AK8: 0 | AL8: 0
B9: Aspect Health Standard Acquisition Fee | D9: Acquisition & Development Fee | E9: 200000 | F9: =E9/$E$5 -> 10.664392 | L9: =D11 -> Closing Costs - Buyer | M9: =E11 -> 80897.21 | N9: =+M9/SF -> 4.3135976 | P9: Total | Q9: =SUM(Q6:Q8) -> 10195210 | R9: =SUM(R6:R8) -> 543.62857 | T9: LC % | U9: 0 | V9: 0 | W9: 0 | X9: 0 | Y9: 0 | Z9: 0 | AA9: 0 | AB9: 0 | AC9: 0.025 | AD9: 0.025 | AE9: 0.025 | AF9: 0.025 | AG9: 0.025 | AH9: 0.0125 | AI9: 0.0125 | AJ9: 0.0125 | AK9: 0.0125 | AL9: 0.0125
B10: Calculated; Required Per Lender Term Sheet Dated 5.02.23 | D10: Lender Rent Escrow | E10: 68000 | F10: =E10/$E$5 -> 3.6258931 | L10: =D12 -> Closing Costs - Lender - Permanent Loan | M10: =E12 -> 16412 | N10: =+M10/SF -> 0.87511997 | T10: LC/RSF | U10: =(U7-U8)*U9 -> 0 | V10: =(V7-V8)*V9 -> 0 | W10: =(W7-W8)*W9 -> 0 | X10: =(X7-X8)*X9 -> 0 | Y10: =(Y7-Y8)*Y9 -> 0 | Z10: =(Z7-Z8)*Z9 -> 0 | AA10: =(AA7-AA8)*AA9 -> 0 | AB10: =(AB7-AB8)*AB9 -> 0 | ... AL10: =(AL7-AL8)*AL9 -> 0.608091
B11: Estimated Based on Hospital Ave/Stratford | D11: Closing Costs - Buyer | E11: ='Closing Costs '!E32+'Closing Costs '!E21 -> 80897.21 | F11: =E11/$E$5 -> 4.3135976 | L11: =D21 -> Lender Origination Fee - Permanent Loan | M11: =E21 -> 32750 | N11: =+M11/SF -> 1.7462941 | P11: =P37 -> Construction Loan @ 0.00% LTC | Q11: =Q37 -> 0 | R11: =+Q11/$E$5 -> 0 | T11: Total LC/RSF
B12: Estimated Based on Hospital Ave/Stratford | D12: Closing Costs - Lender - Permanent Loan | E12: ='Closing Costs '!E10 -> 16412 | F12: =E12/$E$5 -> 0.87511997 | L12: =D13 -> Closing Costs - Lender - Construction Loan | M12: =E13 -> 0 | N12: =+M12/SF -> 0 | P12: =P38 -> Equity Contribution @ 100.00% LTC | Q12: =Q38 -> 200000 | R12: =+Q12/$E$5 -> 10.664392
B13: Estimated Based on Hospital Ave/Stratford | D13: Closing Costs - Lender - Construction Loan | E13: 0 | F13: =E13/$E$5 -> 0 | L13: =D22 -> Lender Origination Fee - Construction Loan | M13: =E22 -> 0 | N13: =+M13/SF -> 0 | P13: Total | Q13: =SUM(Q11:Q12) -> 200000 | R13: =SUM(R11:R12) -> 10.664392 | T13: RSF | U13: =SF -> 18754 | V13: =U13 -> 18754 | W13: =V13 -> 18754 | X13: =W13 -> 18754 | Y13: =X13 -> 18754 | Z13: =Y13 -> 18754 | AA13: =Z13 -> 18754 | AB13: =AA13 -> 18754 | AC13: =AB13 -> 18754 | ... AL13: =AK13 -> 18754
D14: Site Acquisition Costs Subtotal | E14: =SUM(E8:E13) -> 10065309 | F14: =E14/$E$5 -> 536.70199 | L14: =D17 -> Construction Costs | M14: =E17 -> 200000 | N14: =+M14/SF -> 10.664392 | T14: LC's per Year | U14: =U10*U13 -> 0 | V14: =V10*V13 -> 0 | W14: =W10*W13 -> 0 | X14: =X10*X13 -> 0 | Y14: =Y10*Y13 -> 0 | Z14: =Z10*Z13 -> 0 | AA14: =AA13*AA10 -> 0 | AB14: =AB13*AB10 -> 0 | AC14: =AC13*AC10 -> 19084.946 | AD14: =AD13*AD10 -> 19466.645 | AE14: =AE13*AE10 -> 19855.978 | AF14: =AF13*AF10 -> 20253.097 | AG14: =AG13*AG10 -> 20658.159 | AH14: =AH13*AH10 -> 10535.661 | ... AL14: =AL13*AL10 -> 11404.139
L15: =D27 -> Leasing Legal | M15: =E27 -> 3381 | N15: =+M15/SF -> 0.18028154
D16: Construction Costs | L16: =D28 -> Broker Fee | M16: =E28 -> 0 | N16: =+M16/SF -> 0 | T16: Total LC's | AL16: =SUM(U14:AL14) -> 154146.83
B17: Pre-Disposition Renovation Costs | D17: Construction Costs | E17: ='Property CF'!AO27 -> 200000 | F17: =E17/$E$5 -> 10.664392
D18: Construction Costs Subtotal | E18: =E17 -> 200000 | F18: =F17 -> 10.664392 | H18: Project Capitalization | I18: =+SUBTOTAL(9,I5:I17) -> 10395210 | J18: =+I18/SF -> 554.29296 | L18: Total Project Cost | M18: =SUM(M5:M17) -> 10395210 | N18: =+M18/SF -> 554.29296 | T18: Leasing Commission Calculation
U19: =1 -> 1 | V19: =U19+1 -> 2 | W19: =V19+1 -> 3 | X19: =W19+1 -> 4 | Y19: =X19+1 -> 5 | Z19: =Y19+1 -> 6 | AA19: =Z19+1 -> 7 | AB19: =AA19+1 -> 8 | AC19: =AB19+1 -> 9 | ... AL19: =AK19+1 -> 18
D20: Development Financing | H20: Sources & Uses Summary - Permanent Loan | P20: =P2 -> 1500 Boston Post Road, Darien
B21: 0.50% of Loan Amount | D21: Lender Origination Fee - Permanent Loan | E21: =Q28 -> 32750 | F21: =E21/$E$5 -> 1.7462941 | H21: Total Capitalization (Sources) | I21: Amount | J21: $ PSF | L21: Total Project Cost (Uses) | M21: Amount | N21: $ PSF | P21: Project Capitalization | T21: Year Ending | U21: 45657 | V21: =EOMONTH(U21,12) -> 46022 | W21: =EOMONTH(V21,12) -> 46387 | X21: =EOMONTH(W21,12) -> 46752 | Y21: =EOMONTH(X21,12) -> 47118 | Z21: =EOMONTH(Y21,12) -> 47483 | AA21: =EOMONTH(Z21,12) -> 47848 | AB21: =EOMONTH(AA21,12) -> 48213
B22: 1.00% of Loan Amount | D22: Lender Origination Fee - Construction Loan | E22: 0 | F22: =E22/$E$5 -> 0
D23: Development Financing Subtotal | E23: =SUM(E21:E22) -> 32750 | F23: =SUM(F21:F22) -> 1.7462941 | H23: =P24 -> Permanent Loan @ 64.25% LTC | I23: =Q24 -> 6550000 | J23: =+I23/SF -> 349.25882 | L23: =L5 -> Occupied Building | M23: =M5 -> 9700000 | N23: =+M23/SF -> 517.22299 | P23: Total Capitalization | Q23: =SUM(E8:E12)+E21+E26+E27 -> 10195210 | R23: =Q23/SF -> 543.62857 | T23: Rental Rate | U23: =29.07*1.1 -> 31.977 | V23: =U23 -> 31.977 | W23: =V23 -> 31.977 | X23: =W23 -> 31.977 | Y23: =X23 -> 31.977 | Z23: =Y23*1.1 -> 35.1747 | AA23: =Z23 -> 35.1747 | AB23: =AA23 -> 35.1747
H24: =P25 -> Equity Contribution @ 35.75% LTC | I24: =Q25 -> 3551440.2 | J24: =+I24/SF -> 189.36975 | L24: =L6 -> Acquisition & Development Fee | M24: =M6 -> 200000 | N24: =+M24/SF -> 10.664392 | P24: =+"Permanent Loan @ "&(TEXT(S24,"0.00% LTC")) -> Permanent Loan @ 64.25% LTC | Q24: 6550000 | R24: =+Q24/$E$5 -> 349.25882 | S24: =Q24/Q23 -> 0.64245855 | T24: Operating Expenses | U24: 15 | V24: =U24*1.02 -> 15.3 | W24: =V24*1.02 -> 15.606 | X24: =W24*1.02 -> 15.91812 | Y24: =X24*1.02 -> 16.236482 | Z24: =Y24*1.02 -> 16.561212 | AA24: =Z24*1.02 -> 16.892436 | AB24: =AA24*1.02 -> 17.230285
D25: Tenant Fit-Out | H25: Addition Equity Contribution | I25: =Q26 -> 93770 | J25: =+I25/SF -> 5 | L25: =L7 -> Tenant Capital Reimbursement | M25: =M7 -> 93770 | N25: =+M25/SF -> 5 | P25: =+"Equity Contribution @ "&(TEXT(S25,"0.00% LTC")) -> Equity Contribution @ 35.75% LTC | Q25: =Q23-Q24-Q26 -> 3551440.2 | R25: =+Q25/$E$5 -> 189.36975 | S25: =1-S24 -> 0.35754145 | T25: LC % | U25: 0.025 | V25: 0.025 | W25: 0.025 | X25: 0.025 | Y25: 0.025 | Z25: 0.0125 | AA25: 0.0125 | AB25: 0.0125
B26: Per Fifth Amendment to Lease Agreement | D26: Tenant Capital Reimbursement | E26: 93770 | F26: =E26/$E$5 -> 5 | L26: =L8 -> Lender Rent Escrow | M26: =M8 -> 68000 | N26: =+M26/SF -> 3.6258931 | P26: Additional Equity Contribution | Q26: =E26 -> 93770 | R26: =+Q26/$E$5 -> 5 | T26: LC/RSF | U26: =(U23+U24)*U25 -> 1.174425 | V26: =(V23+V24)*V25 -> 1.181925 | W26: =(W23+W24)*W25 -> 1.189575 | X26: =(X23+X24)*X25 -> 1.197378 | Y26: =(Y23+Y24)*Y25 -> 1.2053371 | Z26: =(Z23+Z24)*Z25 -> 0.6466989 | AA26: =(AA23+AA24)*AA25 -> 0.6508392 | AB26: =(AB23+AB24)*AB25 -> 0.65506231
B27: Per McGuire Woods Invoice | D27: Leasing Legal | E27: 3381 | F27: =E27/$E$5 -> 0.18028154 | L27: =L9 -> Closing Costs - Buyer | M27: =M9 -> 80897.21 | N27: =+M27/SF -> 4.3135976 | T27: Total LC/RSF
B28: Based on Leasing Commission Sheet, 5.00% Year 1-5, 2.50% Year 6-10, 1.00% Year 11-15 | D28: Broker Fee | E28: 0 | F28: =E28/$E$5 -> 0 | L28: =L10 -> Closing Costs - Lender - Permanent Loan | M28: =M10 -> 16412 | N28: =+M28/SF -> 0.87511997 | P28: Origination Fee | Q28: =+Q24*S28 -> 32750 | R28: =+Q28/$E$5 -> 1.7462941 | S28: 0.005
D29: Development Financing Subtotal | E29: =SUM(E26:E28) -> 97151 | F29: =SUM(F26:F28) -> 5.1802815 | L29: =L11 -> Lender Origination Fee - Permanent Loan | M29: =M11 -> 32750 | N29: =+M29/SF -> 1.7462941 | T29: RSF | U29: =SF -> 18754 | V29: =U29 -> 18754 | W29: =V29 -> 18754 | X29: =W29 -> 18754 | Y29: =X29 -> 18754 | Z29: =Y29 -> 18754 | AA29: =Z29 -> 18754 | AB29: =AA29/3 -> 6251.3333
L30: =L15 -> Leasing Legal | M30: =M15 -> 3381 | N30: =+M30/SF -> 0.18028154 | T30: LC's per Year | U30: =U26*U29 -> 22025.166 | V30: =V26*V29 -> 22165.821 | W30: =W26*W29 -> 22309.29 | X30: =X26*X29 -> 22455.627 | Y30: =Y26*Y29 -> 22604.891 | Z30: =Z26*Z29 -> 12128.191 | AA30: =AA29*AA26 -> 12205.838 | AB30: =AB29*AB26 -> 4095.0129
D31: Total Development Cost | E31: =E14+E18+E23+E29 -> 10395210 | F31: =+E31/$E$5 -> 554.29296 | G31: =E33/E31 -> 0.063931729
H32: Project Capitalization | I32: =+SUBTOTAL(9,I23:I31) -> 10195210 | J32: =+I32/SF -> 543.62857 | L32: Total Project Cost | M32: =SUM(M23:M31) -> 10195210 | N32: =+M32/SF -> 543.62857 | T32: Total LC's | AL32: =SUM(U30:AL30) -> 139989.84
D33: Existing Base Rental Rate | E33: ='Offering Memorandum'!BA14 -> 664583.76 | F33: =E33/SF -> 35.436907 | G33: =E33/E31 -> 0.063931729 | P33: =P20 -> 1500 Boston Post Road, Darien
H34: Sources & Uses Summary - Additional Equity | P34: Project Capitalization
H35: Total Capitalization (Sources) | I35: Amount | J35: $ PSF | L35: Total Project Cost (Uses) | M35: Amount | N35: $ PSF
P36: Total Capitalization | Q36: =E17+E13+E22 -> 200000 | R36: =Q36/SF -> 10.664392
H37: =P37 -> Construction Loan @ 0.00% LTC | I37: =Q37 -> 0 | J37: =+I37/SF -> 0 | L37: =L14 -> Construction Costs | M37: =M14 -> 200000 | N37: =+M37/SF -> 10.664392 | P37: =+"Construction Loan @ "&(TEXT(S37,"0.00% LTC")) -> Construction Loan @ 0.00% LTC | Q37: =Q36*S37 -> 0 | R37: =+Q37/$E$5 -> 0 | S37: 0
H38: =P38 -> Equity Contribution @ 100.00% LTC | I38: =Q38 -> 200000 | J38: =+I38/SF -> 10.664392 | L38: =L16 -> Broker Fee | M38: =M16 -> 0 | N38: =+M38/SF -> 0 | P38: =+"Equity Contribution @ "&(TEXT(S38,"0.00% LTC")) -> Equity Contribution @ 100.00% LTC | Q38: =Q36-Q37 -> 200000 | R38: =+Q38/$E$5 -> 10.664392 | S38: =1-S37 -> 1
L39: =L12 -> Closing Costs - Lender - Construction Loan | M39: =M12 -> 0 | N39: =+M39/SF -> 0 | P39: Additional Equity Contribution | Q39: =Q36-SUM(Q37:Q38) -> 0 | R39: =+Q39/$E$5 -> 0
L40: =L13 -> Lender Origination Fee - Construction Loan | M40: =M13 -> 0 | N40: =+M40/SF -> 0
P41: Origination Fee | Q41: =+Q37*S41 -> 0 | R41: =+Q41/$E$5 -> 0 | S41: 0.01
H43: Project Capitalization | I43: =+SUBTOTAL(9,I37:I42) -> 200000 | J43: =+I43/SF -> 10.664392 | L43: Total Project Cost | M43: =SUM(M37:M41) -> 200000 | N43: =+M43/SF -> 10.664392

Sheet Property CF
B4: Acquisition Assumptions | E4: Project Development Schedule | AR4: Welltower JV Assumptions | AU4: CASH FLOW | BI4: Levered Development Returns to Equity | BM4: Levered Deal Returns to Equity - Year 5 | BQ4: Aspect Health, Inc. Fee Schedule - Year 5 Sale
B5: Property | F5: Start | G5: Term | H5: =0 -> 0 | I5: =H5+1 -> 1 | J5: =I5+1 -> 2 | K5: =J5+1 -> 3 | L5: =K5+1 -> 4 | M5: =L5+1 -> 5 | N5: =M5+1 -> 6 | O5: =N5+1 -> 7 | P5: =O5+1 -> 8 | ... AN5: =AM5+1 -> 32 | AO5: Total | AP5: PSF | AR5: Property | AU5: =Budget!D2 -> 1500 Boston Post Road, Darien | BI5: Project-Level | BJ5: Amount | BK5: $PSF | BM5: Project-Level Returns | BN5: Amount | BO5: $ PSF | BQ5: Self-Perform + Welltower JV
B6: Total Acquisition Cost | C6: =Budget!E31 -> 10395210 | AR6: Property Size (RSF) | AS6: =SF -> 18754 | BI6: Total Proceeds | BJ6: =SUMIF(H144:AN145,">0") -> 4696380.2 | BK6: =BJ6/SF -> 250.42019 | BM6: Total Proceeds | BN6: =SUM(BB81:BB85) -> 6423201.1 | BO6: =BN6/$AS$6 -> 342.49766
E7: Month Ending | H7: 45120 | I7: =EOMONTH(H7,0) -> 45138 | J7: =EOMONTH(I7,1) -> 45169 | K7: =EOMONTH(J7,1) -> 45199 | L7: =EOMONTH(K7,1) -> 45230 | M7: =EOMONTH(L7,1) -> 45260 | N7: =EOMONTH(M7,1) -> 45291 | O7: =EOMONTH(N7,1) -> 45322 | P7: =EOMONTH(O7,1) -> 45351 | Q7: =EOMONTH(P7,1) -> 45382 | ... AN7: =EOMONTH(AM7,1) -> 46081 | AR7: Starting Rent (RSF) | AS7: =AW12/AS6 -> 36.930006 | AV7: 0 | AW7: =AV7+1 -> 1 | AY7: =AW7+1 -> 2 | AZ7: =AY7+1 -> 3 | BA7: =AZ7+1 -> 4 | BB7: =BA7+1 -> 5 | BC7: =BB7+1 -> 6 | BD7: =BC7+1 -> 7 | BE7: =BD7+1 -> 8 | BF7: =BE7+1 -> 9 | BG7: =BF7+1 -> 10 | BI7: Capital Contribution | BJ7: =SUMIF(H144:AN145,"<0") -> -3895347.3 | BK7: =-BJ7/SF -> 207.70754 | BM7: Capital Contribution | BN7: =AV44 -> -4154538.5 | BO7: =BN7/-$AS$6 -> 221.52812 | BR7: =0 -> 0 | BS7: =BR7+1 -> 1 | BT7: =BS7+1 -> 2 | BU7: =BT7+1 -> 3 | BV7: =BU7+1 -> 4 | BW7: =BV7+1 -> 5
B8: Debt | AR8: Total Valuation - All-In Gross Sale Price Welltower | AS8: =AS71 -> 11870110 | AU8: Year Ending | AV8: =AL7 -> 46022 | AW8: =EOMONTH(AV8,12) -> 46387 | AY8: =EOMONTH(AW8,12) -> 46752 | AZ8: =EOMONTH(AY8,12) -> 47118 | BA8: =EOMONTH(AZ8,12) -> 47483 | BB8: =EOMONTH(BA8,12) -> 47848 | BC8: =EOMONTH(BB8,12) -> 48213 | BD8: =EOMONTH(BC8,12) -> 48579 | BE8: =EOMONTH(BD8,12) -> 48944 | BF8: =EOMONTH(BE8,12) -> 49309 | BG8: =EOMONTH(BF8,12) -> 49674 | BI8: Net Profit | BJ8: =BJ6+BJ7 -> 801032.86 | BK8: =BJ8/SF -> 42.712641 | BM8: Net Profit | BN8: =BN6+BN7 -> 2268662.6 | BO8: =BN8/$AS$6 -> 120.96953 | BQ8: Year Ending | BR8: =AN7 -> 46081 | BS8: =EOMONTH(BR8,12) -> 46446 | BT8: =EOMONTH(BS8,12) -> 46812 | BU8: =EOMONTH(BT8,12) -> 47177 | BV8: =EOMONTH(BU8,12) -> 47542 | BW8: =EOMONTH(BV8,12) -> 47907
B9: Permanent LTC | C9: =Budget!S24 -> 0.64245855 | AR9: Total Valuation per RSF | AS9: =AS8/AS6 -> 632.9375
B10: Permanent Interest Rate Spread | C10: ='Offering Memorandum'!BG4+'Offering Memorandum'!BH4+'Offering Memorandum'!BI4+'Offering Memorandum'!BJ4 -> 0.0226 | E10: Effective Gross Rent | I10: =I12+I11 -> 52850.495 | J10: =J12+J11 -> 70436.913 | K10: =K12+K11 -> 70436.913 | L10: =L12+L11 -> 70436.913 | M10: =M12+M11 -> 70436.913 | N10: =N12+N11 -> 25005.333 | O10: =O12+O11 -> 25005.333 | P10: =P12+P11 -> 80387.313 | ... AL10: =AL12+AL11 -> 26015.549 | AM10: 0 | AN10: 0 | AO10: =SUM(H10:AN10) -> 2145989.5 | AP10: =+AO10/SF -> 114.42836 | AR10: Term (Yrs) | AS10: 15.25 | AU10: Effective Gross Rent | AW10: =AW12+AW11 -> 992649.33 | AY10: =AY12+AY11 -> 1012502.3 | AZ10: =AZ12+AZ11 -> 1032752.4 | BA10: =BA12+BA11 -> 1053407.4 | BB10: =BB12+BB11 -> 1074475.6 | BC10: =BC12+BC11 -> 1095965.1 | BD10: =BD12+BD11 -> 1117884.4 | BE10: =BE12+BE11 -> 1140242.1 | BF10: =BF12+BF11 -> 1163046.9 | BG10: =BG12+BG11 -> 1186307.8 | BI10: IRR | BJ10: =F61 -> 0.089599493 | BM10: IRR | BN10: =BB49 -> 0.10594725 | BQ10: Acquisition & Development Fee | BR10: =BR24 -> 200000
B11: Loan Index Rate | C11: ='Offering Memorandum'!BM4 -> 0.0411 | E11: Operating Expenses | I11: =AS19*SF/12 -> 25005.333 | J11: =I11 -> 25005.333 | K11: =J11 -> 25005.333 | L11: =K11 -> 25005.333 | M11: =L11 -> 25005.333 | N11: =M11 -> 25005.333 | O11: =N11 -> 25005.333 | P11: =O11 -> 25005.333 | Q11: =P11 -> 25005.333 | ... U11: =T11 -> 25005.333 | V11: =J11*1.02 -> 25505.44 | W11: =K11*1.02 -> 25505.44 | X11: =L11*1.02 -> 25505.44 | Y11: =M11*1.02 -> 25505.44 | Z11: =N11*1.02 -> 25505.44 | AA11: =O11*1.02 -> 25505.44 | AB11: =P11*1.02 -> 25505.44 | AC11: =Q11*1.02 -> 25505.44 | ... AL11: =Z11*1.02 -> 26015.549 | AM11: 0 | AN11: 0 | AO11: =SUM(H11:AN11) -> 761212.36 | AP11: =+AO11/SF -> 40.589333 | AR11: Asset Management Fee % (Equity) | AS11: 0.0025 | AU11: Operating Expenses | AW11: =AS19*AS6 -> 300064 | AY11: =AW11*(1+$AS$20) -> 306065.28 | AZ11: =AY11*(1+$AS$20) -> 312186.59 | BA11: =AZ11*(1+$AS$20) -> 318430.32 | BB11: =BA11*(1+$AS$20) -> 324798.92 | BC11: =BB11*(1+$AS$20) -> 331294.9 | BD11: =BC11*(1+$AS$20) -> 337920.8 | BE11: =BD11*(1+$AS$20) -> 344679.22 | BF11: =BE11*(1+$AS$20) -> 351572.8 | BG11: =BF11*(1+$AS$20) -> 358604.26 | BI11: Equity Multiple | BJ11: =BJ8/-BJ7+1 -> 1.2056384 | BM11: Equity Multiple | BN11: =BN8/-BN7+1 -> 1.5460685 | BQ11: Inside Fee | BR11: ='Property CF'!$AS$8*$BR$25 -> 237402.2 | BS11: 0 | BT11: 0 | BU11: 0 | BV11: 0 | BW11: 0
B12: All-In Interest Rate | C12: =C10+C11 -> 0.0637 | E12: NOI | I12: ='Offering Memorandum'!BA5/12*(((_xlfn.DAYS(I7,H7-1))/_xlfn.DAYS(I7,EOMONTH(I7,-1)))) -> 27845.162 | J12: ='Offering Memorandum'!BA5/12 -> 45431.58 | K12: =J12 -> 45431.58 | L12: =K12 -> 45431.58 | M12: =L12 -> 45431.58 | N12: 0 | O12: =N12 -> 0 | P12: =Budget!E33/12 -> 55381.98 | Q12: =P12 -> 55381.98 | R12: =Q12 -> 55381.98 | S12: =R12 -> 55381.98 | T12: =S12 -> 55381.98 | U12: =T12 -> 55381.98 | V12: =U12 -> 55381.98 | W12: =V12 -> 55381.98 | X12: =W12 -> 55381.98 | Y12: =X12 -> 55381.98 | Z12: 0 | AA12: =(Y12)*(1+$AS$13) -> 56489.619 | AB12: =AA12 -> 56489.619 | AC12: =AB12 -> 56489.619 | AD12: =AC12 -> 56489.619 | AE12: =AD12 -> 56489.619 | AF12: =AE12 -> 56489.619 | AG12: =AF12 -> 56489.619 | AH12: =AG12 -> 56489.619 | AI12: =AH12 -> 56489.619 | ... AK12: =AJ12 -> 56489.619 | AL12: 0 | AM12: 0 | AN12: 0 | AO12: =SUM(H12:AN12) -> 1384777.1 | AP12: =+AO12/SF -> 73.839026 | AR12: Capital Reserves (RSF) | AS12: 0 | AU12: Net Operating Income | AW12: =(SUM(AA12:AL12)*(1+$AS$13))+(AK12*(1+$AS$13))*(1+$AS$13) -> 692585.33 | AY12: =AW12*(1+$AS$13) -> 706437.04 | AZ12: =AY12*(1+$AS$13) -> 720565.78 | BA12: =AZ12*(1+$AS$13) -> 734977.09 | BB12: =BA12*(1+$AS$13) -> 749676.64 | BC12: =BB12*(1+$AS$13) -> 764670.17 | BD12: =BC12*(1+$AS$13) -> 779963.57 | BE12: =BD12*(1+$AS$13) -> 795562.84 | BF12: =BE12*(1+$AS$13) -> 811474.1 | BG12: =BF12*(1+$AS$13) -> 827703.58 | BM12: Avg. Cash-on-Cash | BN12: =BB47 -> 0.095691193 | BQ12: Management Fee | BR12: 0 | BS12: ='Property CF'!AW10*$BR$26 -> 0 | BT12: ='Property CF'!AY10*$BR$26 -> 0 | BU12: ='Property CF'!AZ10*$BR$26 -> 0 | BV12: ='Property CF'!BA10*$BR$26 -> 0 | BW12: ='Property CF'!BB10*$BR$26 -> 0
B13: Loan Amount | C13: =Budget!Q24 -> 6550000 | E13: Asset Management Fee | F13: Accrue? | G13: Yes | I13: =I10*$BR$27 -> 1057.0099 | J13: =J10*$BR$27 -> 1408.7383 | K13: =K10*$BR$27 -> 1408.7383 | L13: =L10*$BR$27 -> 1408.7383 | M13: =M10*$BR$27 -> 1408.7383 | N13: =N10*$BR$27 -> 500.10667 | O13: =O10*$BR$27 -> 500.10667 | P13: =P10*$BR$27 -> 1607.7463 | ... AL13: =AL10*$BR$27 -> 520.31098 | AM13: 0 | AN13: 0 | AO13: =SUM(H13:AN13) -> 42919.789 | AP13: =+AO13/SF -> 2.2885672 | AR13: Rent Escalator % | AS13: 0.02 | AU13: Rental Rate per RSF | AW13: =AW12/SF -> 36.930006 | AY13: =AY12/SF -> 37.668606 | AZ13: =AZ12/SF -> 38.421978 | BA13: =BA12/SF -> 39.190418 | BB13: =BB12/SF -> 39.974226 | BC13: =BC12/SF -> 40.773711 | BD13: =BD12/SF -> 41.589185 | BE13: =BE12/SF -> 42.420968 | BF13: =BF12/SF -> 43.269388 | BG13: =BG12/SF -> 44.134776 | BI13: Levered Development Returns to Equity | BQ13: Asset Management Fee | BR13: =SUM(AO13) -> 42919.789 | BS13: =-'Property CF'!AW43 -> 10386.346 | BT13: =-'Property CF'!AY43 -> 10386.346 | BU13: =-'Property CF'!AZ43 -> 10386.346 | BV13: =-'Property CF'!BA43 -> 10386.346 | BW13: =-'Property CF'!BB43 -> 10386.346
E14: Lender Escrow/Additional Return | G14: Yes | I14: 0 | J14: 0 | K14: 0 | L14: 0 | M14: 0 | N14: =H19 -> 68000 | O14: 0 | P14: 0 | Q14: 0 | R14: 0 | S14: 0 | T14: 0 | U14: 0 | V14: 0 | W14: 0 | X14: 0 | Y14: 0 | Z14: 0 | AA14: 0 | AB14: 0 | AC14: 0 | AD14: 0 | AE14: 0 | AF14: 0 | AG14: 0 | AH14: 0 | AI14: 0 | AJ14: 0 | AK14: 0 | AL14: 0 | AM14: 0 | AN14: 0 | AO14: =SUM(H14:AN14) -> 68000 | AP14: =+AO14/SF -> 3.6258931 | AR14: Year 1 Going-In Cap Rate | AS14: 0.0595 | AU14: Capital Reserves | AW14: =AS12*AS6 -> 0 | AY14: =AW14 -> 0 | AZ14: =AY14 -> 0 | BA14: =AZ14 -> 0 | BB14: =BA14 -> 0 | BC14: =BB14 -> 0 | BD14: =BC14 -> 0 | BE14: =BD14 -> 0 | BF14: =BE14 -> 0 | BG14: =BF14 -> 0 | BI14: Doctors Interest | BJ14: Amount | BK14: $PSF | BM14: Levered Deal Returns to Equity - Year 5
B15: Equity | G15: No | AR15: Year 2 Exit Cap Rate | AS15: 0.0585 | AU15: Tenant Improvement Allowance | AW15: 0 | AY15: 0 | AZ15: 0 | BA15: 0 | BB15: 0 | BC15: 0 | BD15: 0 | BE15: 0 | BF15: 0 | BG15: 0 | BI15: Total Proceeds | BJ15: =SUM(I105:AN105) -> 0 | BK15: =BJ15/SF -> 0 | BM15: Aspect Health Inc. Returns | BN15: Amount | BO15: $ PSF | BQ15: Yearly Total | BR15: =SUM(BR10:BR13) -> 480321.99 | BS15: =SUM(BS10:BS13) -> 10386.346 | BT15: =SUM(BT10:BT13) -> 10386.346 | BU15: =SUM(BU10:BU13) -> 10386.346 | BV15: =SUM(BV10:BV13) -> 10386.346 | BW15: =SUM(BW10:BW13) -> 10386.346
B16: Required Initial Common Capital Contributions | C16: =Budget!Q25 -> 3551440.2 | E16: =Budget!D7 -> Site Acquisition Costs | AR16: Year 3-10 Exit Cap Rate Adjustment per Year | AS16: 0.0005 | AU16: Net Cash Flow Before Debt Service | AW16: =AW12-SUM(AW14:AW15) -> 692585.33 | AY16: =AY12-SUM(AY14:AY15) -> 706437.04 | AZ16: =AZ12-SUM(AZ14:AZ15) -> 720565.78 | BA16: =BA12-SUM(BA14:BA15) -> 734977.09 | BB16: =BB12-SUM(BB14:BB15) -> 749676.64 | BC16: =BC12-SUM(BC14:BC15) -> 764670.17 | BD16: =BD12-SUM(BD14:BD15) -> 779963.57 | BE16: =BE12-SUM(BE14:BE15) -> 795562.84 | BF16: =BF12-SUM(BF14:BF15) -> 811474.1 | BG16: =BG12-SUM(BG14:BG15) -> 827703.58 | BI16: Capital Contribution | BJ16: =H105 -> 0 | BK16: =-BJ16/SF -> 0 | BM16: Total Proceeds | BN16: ='JV Waterfall'!T36 -> 642320.11 | BO16: =BN16/$AS$6 -> 34.249766
B17: Tenant Capital Reimbursement Equity Contribution | C17: =Budget!Q8 -> 93770 | E17: =Budget!D8 -> Occupied Building | F17: 0 | G17: 0 | H17: =IF(AND(H$5>=$F17,H$5<=$G17),$AO17/($G17-$F17+1),0) -> 9700000 | I17: =IF(AND(I$5>=$F17,I$5<=$G17),$AO17/($G17-$F17+1),0) -> 0 | J17: =IF(AND(J$5>=$F17,J$5<=$G17),$AO17/($G17-$F17+1),0) -> 0 | K17: =IF(AND(K$5>=$F17,K$5<=$G17),$AO17/($G17-$F17+1),0) -> 0 | L17: =IF(AND(L$5>=$F17,L$5<=$G17),$AO17/($G17-$F17+1),0) -> 0 | M17: =IF(AND(M$5>=$F17,M$5<=$G17),$AO17/($G17-$F17+1),0) -> 0 | N17: =IF(AND(N$5>=$F17,N$5<=$G17),$AO17/($G17-$F17+1),0) -> 0 | O17: =IF(AND(O$5>=$F17,O$5<=$G17),$AO17/($G17-$F17+1),0) -> 0 | ... AN17: =IF(AND(AN$5>=$F17,AN$5<=$G17),$AO17/($G17-$F17+1),0) -> 0 | AO17: =Budget!E8 -> 9700000 | AP17: =+AO17/SF -> 517.22299 | AR17: Tenant Improvement Allowance (RSF) | AS17: 15 | AU17: Unlevered Cash Flow | AV17: =-AS8 -> -11870110 | AW17: =AW16 -> 692585.33 | AY17: =AY16 -> 706437.04 | AZ17: =AZ16 -> 720565.78 | BA17: =BA16 -> 734977.09 | BB17: =BB16 -> 749676.64 | BC17: =BC16 -> 764670.17 | BD17: =BD16 -> 779963.57 | BE17: =BE16 -> 795562.84 | BF17: =BF16 -> 811474.1 | BG17: =BG16 -> 827703.58 | BI17: Net Profit | BJ17: =BJ15+BJ16 -> 0 | BK17: =BJ17/SF -> 0 | BM17: Total Asset Management Fee's | BN17: ='JV Waterfall'!T37 -> 51931.731 | BO17: =BN17/$AS$6 -> 2.7691016 | BQ17: Hold Period Total | BR17: =SUM(BR15:BW15) -> 532253.72
B18: Construction Cost Equity Contribution | C18: =Budget!Q38 -> 200000 | E18: =Budget!D9 -> Acquisition & Development Fee | F18: 0 | G18: 0 | H18: =IF(AND(H$5>=$F18,H$5<=$G18),$AO18/($G18-$F18+1),0) -> 200000 | I18: =IF(AND(I$5>=$F18,I$5<=$G18),$AO18/($G18-$F18+1),0) -> 0 | J18: =IF(AND(J$5>=$F18,J$5<=$G18),$AO18/($G18-$F18+1),0) -> 0 | K18: =IF(AND(K$5>=$F18,K$5<=$G18),$AO18/($G18-$F18+1),0) -> 0 | L18: =IF(AND(L$5>=$F18,L$5<=$G18),$AO18/($G18-$F18+1),0) -> 0 | M18: =IF(AND(M$5>=$F18,M$5<=$G18),$AO18/($G18-$F18+1),0) -> 0 | N18: =IF(AND(N$5>=$F18,N$5<=$G18),$AO18/($G18-$F18+1),0) -> 0 | O18: =IF(AND(O$5>=$F18,O$5<=$G18),$AO18/($G18-$F18+1),0) -> 0 | ... AN18: =IF(AND(AN$5>=$F18,AN$5<=$G18),$AO18/($G18-$F18+1),0) -> 0 | AO18: =Budget!E9 -> 200000 | AP18: =+AO18/SF -> 10.664392 | AR18: Renewal Term (Yrs) | AS18: 5 | BM18: Capital Contribution | BN18: =BN47 -> -415453.85 | BO18: =BN18/-$AS$6 -> 22.152812
B19: Required Final Common Capital Contributions | C19: =C16+C17+C18 -> 3845210.2 | E19: =Budget!D10 -> Lender Rent Escrow | F19: 0 | G19: 0 | H19: =IF(AND(H$5>=$F19,H$5<=$G19),$AO19/($G19-$F19+1),0) -> 68000 | I19: =IF(AND(I$5>=$F19,I$5<=$G19),$AO19/($G19-$F19+1),0) -> 0 | J19: =IF(AND(J$5>=$F19,J$5<=$G19),$AO19/($G19-$F19+1),0) -> 0 | K19: =IF(AND(K$5>=$F19,K$5<=$G19),$AO19/($G19-$F19+1),0) -> 0 | L19: =IF(AND(L$5>=$F19,L$5<=$G19),$AO19/($G19-$F19+1),0) -> 0 | M19: =IF(AND(M$5>=$F19,M$5<=$G19),$AO19/($G19-$F19+1),0) -> 0 | N19: =IF(AND(N$5>=$F19,N$5<=$G19),$AO19/($G19-$F19+1),0) -> 0 | O19: =IF(AND(O$5>=$F19,O$5<=$G19),$AO19/($G19-$F19+1),0) -> 0 | ... AN19: =IF(AND(AN$5>=$F19,AN$5<=$G19),$AO19/($G19-$F19+1),0) -> 0 | AO19: =Budget!E10 -> 68000 | AP19: =+AO19/SF -> 3.6258931 | AR19: Operating Expenses (RSF) | AS19: 16 | AU19: WALT | AW19: =$AS$10-AW7 -> 14.25 | AY19: =$AS$10-AY7 -> 13.25 | AZ19: =$AS$10-AZ7 -> 12.25 | BA19: =$AS$10-BA7 -> 11.25 | BB19: =$AS$10-BB7 -> 10.25 | BC19: =$AS$10-BC7 -> 9.25 | BD19: =$AS$10-BD7 -> 8.25 | BE19: =$AS$10-BE7 -> 7.25 | BF19: =$AS$10-BF7 -> 6.25 | BG19: =$AS$10-BG7 -> 5.25 | BI19: IRR | BJ19: =IFERROR(F105,0) -> 0 | BM19: Net Profit | BN19: =BN16+BN17+BN18 -> 278797.99 | BO19: =BN19/$AS$6 -> 14.866055 | BQ19: Total Project Profit | BR19: =BN66 -> 226866.26
E20: =Budget!D11 -> Closing Costs - Buyer | F20: 0 | G20: 0 | H20: =IF(AND(H$5>=$F20,H$5<=$G20),$AO20/($G20-$F20+1),0) -> 80897.21 | I20: =IF(AND(I$5>=$F20,I$5<=$G20),$AO20/($G20-$F20+1),0) -> 0 | J20: =IF(AND(J$5>=$F20,J$5<=$G20),$AO20/($G20-$F20+1),0) -> 0 | K20: =IF(AND(K$5>=$F20,K$5<=$G20),$AO20/($G20-$F20+1),0) -> 0 | L20: =IF(AND(L$5>=$F20,L$5<=$G20),$AO20/($G20-$F20+1),0) -> 0 | M20: =IF(AND(M$5>=$F20,M$5<=$G20),$AO20/($G20-$F20+1),0) -> 0 | N20: =IF(AND(N$5>=$F20,N$5<=$G20),$AO20/($G20-$F20+1),0) -> 0 | O20: =IF(AND(O$5>=$F20,O$5<=$G20),$AO20/($G20-$F20+1),0) -> 0 | ... AN20: =IF(AND(AN$5>=$F20,AN$5<=$G20),$AO20/($G20-$F20+1),0) -> 0 | AO20: =Budget!E11 -> 80897.21 | AP20: =+AO20/SF -> 4.3135976 | AR20: Operating Expense Inflation % | AS20: 0.02 | BI20: Equity Multiple | BJ20: =IFERROR(BJ17/-BJ16,0) -> 0 | BQ20: Total Project + Fee Profit | BR20: =BR17+BR19 -> 759119.98
B21: Aspect Equity Interest % | C21: 1 | E21: =Budget!D12 -> Closing Costs - Lender - Permanent Loan | F21: 0 | G21: 0 | H21: =IF(AND(H$5>=$F21,H$5<=$G21),$AO21/($G21-$F21+1),0) -> 16412 | I21: =IF(AND(I$5>=$F21,I$5<=$G21),$AO21/($G21-$F21+1),0) -> 0 | J21: =IF(AND(J$5>=$F21,J$5<=$G21),$AO21/($G21-$F21+1),0) -> 0 | K21: =IF(AND(K$5>=$F21,K$5<=$G21),$AO21/($G21-$F21+1),0) -> 0 | L21: =IF(AND(L$5>=$F21,L$5<=$G21),$AO21/($G21-$F21+1),0) -> 0 | M21: =IF(AND(M$5>=$F21,M$5<=$G21),$AO21/($G21-$F21+1),0) -> 0 | N21: =IF(AND(N$5>=$F21,N$5<=$G21),$AO21/($G21-$F21+1),0) -> 0 | O21: =IF(AND(O$5>=$F21,O$5<=$G21),$AO21/($G21-$F21+1),0) -> 0 | ... AN21: =IF(AND(AN$5>=$F21,AN$5<=$G21),$AO21/($G21-$F21+1),0) -> 0 | AO21: =Budget!E12 -> 16412 | AP21: =+AO21/SF -> 0.87511997 | AU21: Cap Rate at Sale | AW21: =IF(AW7<=$AY$7,$AS$15,$AS$15+((AW7-$AY$7)*$AS$16)) -> 0.0585 | AY21: =IF(AY7<=$AY$7,$AS$15,$AS$15+((AY7-$AY$7)*$AS$16)) -> 0.0585 | AZ21: =IF(AZ7<=$AY$7,$AS$15,$AS$15+((AZ7-$AY$7)*$AS$16)) -> 0.059 | BA21: =IF(BA7<=$AY$7,$AS$15,$AS$15+((BA7-$AY$7)*$AS$16)) -> 0.0595 | BB21: =IF(BB7<=$AY$7,$AS$15,$AS$15+((BB7-$AY$7)*$AS$16)) -> 0.06 | BC21: =IF(BC7<=$AY$7,$AS$15,$AS$15+((BC7-$AY$7)*$AS$16)) -> 0.0605 | BD21: =IF(BD7<=$AY$7,$AS$15,$AS$15+((BD7-$AY$7)*$AS$16)) -> 0.061 | BE21: =IF(BE7<=$AY$7,$AS$15,$AS$15+((BE7-$AY$7)*$AS$16)) -> 0.0615 | BF21: =IF(BF7<=$AY$7,$AS$15,$AS$15+((BF7-$AY$7)*$AS$16)) -> 0.062 | BG21: =IF(BG7<=$AY$7,$AS$15,$AS$15+((BG7-$AY$7)*$AS$16)) -> 0.0625 | BM21: IRR | BN21: ='JV Waterfall'!T40 -> 0.13028361
B22: Doctor's Equity Interest % | C22: =1-C21 -> 0 | E22: =Budget!D13 -> Closing Costs - Lender - Construction Loan | F22: 9 | G22: 9 | H22: =IF(AND(H$5>=$F22,H$5<=$G22),$AO22/($G22-$F22+1),0) -> 0 | I22: =IF(AND(I$5>=$F22,I$5<=$G22),$AO22/($G22-$F22+1),0) -> 0 | J22: =IF(AND(J$5>=$F22,J$5<=$G22),$AO22/($G22-$F22+1),0) -> 0 | K22: =IF(AND(K$5>=$F22,K$5<=$G22),$AO22/($G22-$F22+1),0) -> 0 | L22: =IF(AND(L$5>=$F22,L$5<=$G22),$AO22/($G22-$F22+1),0) -> 0 | M22: =IF(AND(M$5>=$F22,M$5<=$G22),$AO22/($G22-$F22+1),0) -> 0 | N22: =IF(AND(N$5>=$F22,N$5<=$G22),$AO22/($G22-$F22+1),0) -> 0 | O22: =IF(AND(O$5>=$F22,O$5<=$G22),$AO22/($G22-$F22+1),0) -> 0 | ... AN22: =IF(AND(AN$5>=$F22,AN$5<=$G22),$AO22/($G22-$F22+1),0) -> 0 | AO22: =Budget!E13 -> 0 | AP22: =+AO22/SF -> 0 | AR22: Fee's, Taxes, and Closing Cost's | AU22: Implied Exit Cap Rate | AW22: =(AW12/$AW$26)*(1-$AS$34) -> 0.05689125 | AY22: =(AY12/$AW$26)*(1-$AS$34) -> 0.058029075 | AZ22: =(AZ12/$AW$26)*(1-$AS$34) -> 0.059189656 | BA22: =(BA12/$AW$26)*(1-$AS$34) -> 0.06037345 | BB22: =(BB12/$AW$26)*(1-$AS$34) -> 0.061580919 | BC22: =(BC12/$AW$26)*(1-$AS$34) -> 0.062812537 | BD22: =(BD12/$AW$26)*(1-$AS$34) -> 0.064068788 | BE22: =(BE12/$AW$26)*(1-$AS$34) -> 0.065350163 | BF22: =(BF12/$AW$26)*(1-$AS$34) -> 0.066657167 | BG22: =(BG12/$AW$26)*(1-$AS$34) -> 0.06799031 | BI22: Levered Development Returns to Equity | BM22: Equity Multiple | BN22: ='JV Waterfall'!T41 -> 1.5460685 | BQ22: Assumptions:
AR23: Cost of Sale - Buyer - Going-In Year | AS23: =AS25+AS24 -> 0.02 | AU23: Accretive (Dilutive) Cap Spread | AW23: =AW22-AW21 -> -0.00160875 | AY23: =AY22-AY21 -> -0.000470925 | AZ23: =AZ22-AZ21 -> 0.0001896565 | BA23: =BA22-BA21 -> 0.00087344963 | BB23: =BB22-BB21 -> 0.0015809186 | BC23: =BC22-BC21 -> 0.002312537 | BD23: =BD22-BD21 -> 0.0030687877 | BE23: =BE22-BE21 -> 0.0038501635 | BF23: =BF22-BF21 -> 0.0046571668 | BG23: =BG22-BG21 -> 0.0054903101 | BI23: Preferred Equity Investors | BJ23: Amount | BK23: $PSF | BQ23: Self-Perform + Welltower JV
B24: Aspect Equity Interest | C24: =C16*C21 -> 3551440.2 | E24: Site Acquisition Costs | H24: =+SUBTOTAL(9,H16:H22) -> 10065309 | I24: =+SUBTOTAL(9,I16:I22) -> 0 | J24: =+SUBTOTAL(9,J16:J22) -> 0 | K24: =+SUBTOTAL(9,K16:K22) -> 0 | L24: =+SUBTOTAL(9,L16:L22) -> 0 | M24: =+SUBTOTAL(9,M16:M22) -> 0 | N24: =+SUBTOTAL(9,N16:N22) -> 0 | O24: =+SUBTOTAL(9,O16:O22) -> 0 | ... AO24: =+SUBTOTAL(9,AO16:AO22) -> 10065309 | AP24: =+AO24/SF -> 536.70199 | AR24: Newmark Venture Transaction Fee | AS24: 0.015 | AU24: REIT GAAP Accounting Cap Rate Average | AW24: =AVERAGE($AW$22:AW22) -> 0.05689125 | AY24: =AVERAGE($AW$22:AY22) -> 0.057460162 | AZ24: =AVERAGE($AW$22:AZ22) -> 0.05803666 | BA24: =AVERAGE($AW$22:BA22) -> 0.058620858 | BB24: =AVERAGE($AW$22:BB22) -> 0.05921287 | BC24: =AVERAGE($AW$22:BC22) -> 0.059812814 | BD24: =AVERAGE($AW$22:BD22) -> 0.060420811 | BE24: =AVERAGE($AW$22:BE22) -> 0.06103698 | BF24: =AVERAGE($AW$22:BF22) -> 0.061661445 | BG24: =AVERAGE($AW$22:BG22) -> 0.062294331 | BI24: Total Proceeds | BJ24: =SUMIF(H144:AN144,">0") -> 4696380.2 | BK24: =BJ24/SF -> 250.42019 | BM24: Unlevered Deal Returns - Year 5 | BQ24: Development Fee | BR24: =Budget!E9 -> 200000
B25: Doctor's Equity Interest | C25: =C16*C22 -> 0 | AR25: JV Closing Cost's | AS25: 0.005 | BI25: Capital Contribution | BJ25: =SUMIF(H144:AN144,"<0") -> -3895347.3 | BK25: =-BJ25/SF -> 207.70754 | BM25: Welltower Returns | BN25: Amount | BO25: $ PSF | BQ25: Inside Fee | BR25: =AS29 -> 0.02
B26: Total Equity Interest | C26: =SUM(C24:C25) -> 3551440.2 | E26: Construction Costs | AR26: Cost of Sale - Seller - Exit Year | AS26: =AS29+ AS28+AS27 -> 0.05 | AU26: Gross Sale Price | AW26: =AW12/AW21 -> 11839065 | AY26: =AY12/AY21 -> 12075847 | AZ26: =AZ12/AZ21 -> 12212979 | BA26: =BA12/BA21 -> 12352556 | BB26: =BB12/BB21 -> 12494611 | BC26: =BC12/BC21 -> 12639176 | BD26: =BD12/BD21 -> 12786288 | BE26: =BE12/BE21 -> 12935981 | BF26: =BF12/BF21 -> 13088292 | BG26: =BG12/BG21 -> 13243257 | BI26: Net Profit | BJ26: =BJ24+BJ25 -> 801032.86 | BK26: =BJ26/SF -> 42.712641 | BM26: Total Proceeds | BN26: =SUM(BB55:BB64) -> 15060999 | BO26: =BN26/$AS$6 -> 803.08195 | BQ26: Property Management Fee | BR26: 0
E27: =Budget!D17 -> Construction Costs | H27: 0 | I27: 0 | J27: 0 | K27: 0 | L27: 0 | M27: 0 | N27: 0 | O27: 0 | P27: 0 | Q27: 0 | R27: 0 | S27: 0 | T27: 0 | U27: 0 | V27: 0 | W27: 0 | X27: 0 | Y27: 0 | Z27: 0 | AA27: 0 | AB27: 0 | AC27: 0 | AD27: 0 | AE27: 0 | AF27: 0 | AG27: 0 | AH27: 0 | AI27: 0 | AJ27: 0 | AK27: 200000 | AL27: 0 | AM27: 0 | AN27: 0 | AO27: =SUM(H27:AN27) -> 200000 | AP27: =+AO27/SF -> 10.664392 | AR27: Connecticut State & Municipal Transfer Tax | AS27: 0.015 | AU27: Gross Sale Price PSF | AW27: =AW26/$AS$6 -> 631.28215 | AY27: =AY26/$AS$6 -> 643.90779 | AZ27: =AZ26/$AS$6 -> 651.21997 | BA27: =BA26/$AS$6 -> 658.66248 | BB27: =BB26/$AS$6 -> 666.2371 | BC27: =BC26/$AS$6 -> 673.94563 | BD27: =BD26/$AS$6 -> 681.78991 | BE27: =BE26/$AS$6 -> 689.77184 | BF27: =BF26/$AS$6 -> 697.89335 | BG27: =BG26/$AS$6 -> 706.15641 | BM27: Capital Contribution | BN27: =BN56 -> -11454656 | BO27: =BN27/-$AS$6 -> 610.78469 | BQ27: Asset Management Fee | BR27: 0.02
B28: Preferred Return % | C28: 0.11 | AR28: Broker (Outside) Fee | AS28: 0.015 | BI28: IRR | BJ28: =F144 -> 0.089599493 | BM28: Net Profit | BN28: =BN26+BN27 -> 3606342.8 | BO28: =BN28/$AS$6 -> 192.29726 | BQ28: Asset Management Fee | BR28: =AS11 -> 0.0025
B29: Preferred Return % of Total Equity Contribution | C29: =C28*C21 -> 0.11 | E29: Construction Costs | H29: =+SUBTOTAL(9,H27) -> 0 | I29: =+SUBTOTAL(9,I27) -> 0 | J29: =+SUBTOTAL(9,J27) -> 0 | K29: =+SUBTOTAL(9,K27) -> 0 | L29: =+SUBTOTAL(9,L27) -> 0 | M29: =+SUBTOTAL(9,M27) -> 0 | N29: =+SUBTOTAL(9,N27) -> 0 | O29: =+SUBTOTAL(9,O27) -> 0 | ... AO29: =+SUBTOTAL(9,AO27) -> 200000 | AP29: =+AO29/SF -> 10.664392 | AR29: Aspect Health (Inside) Fee | AS29: 0.02 | AU29: Net Sale Price | AW29: =AW26*(1-($AS$34)) -> 11513491 | AY29: =AY26*(1-($AS$34)) -> 11743761 | AZ29: =AZ26*(1-($AS$34)) -> 11877122 | BA29: =BA26*(1-($AS$34)) -> 12012861 | BB29: =BB26*(1-($AS$34)) -> 12151009 | BC29: =BC26*(1-($AS$34)) -> 12291599 | BD29: =BD26*(1-($AS$34)) -> 12434665 | BE29: =BE26*(1-($AS$34)) -> 12580242 | BF29: =BF26*(1-($AS$34)) -> 12728364 | BG29: =BG26*(1-($AS$34)) -> 12879068 | BI29: Average Cash-on-Cash | BJ29: =AL163 -> 0
B30: Equity Kicker % | C30: 0.2 | AR30: Accrued Asset Management Fees | AS30: =IF($G$13="Yes",SUM(I13:AL13),0) -> 42919.789 | AU30: Net Sale Price PSF | AW30: =AW29/$AS$6 -> 613.92189 | AY30: =AY29/$AS$6 -> 626.20033 | AZ30: =AZ29/$AS$6 -> 633.31142 | BA30: =BA29/$AS$6 -> 640.54926 | BB30: =BB29/$AS$6 -> 647.91558 | BC30: =BC29/$AS$6 -> 655.41212 | BD30: =BD29/$AS$6 -> 663.04069 | BE30: =BE29/$AS$6 -> 670.80312 | BF30: =BF29/$AS$6 -> 678.70128 | BG30: =BG29/$AS$6 -> 686.73711 | BI30: Equity Multiple | BJ30: =BJ26/-BJ25+1 -> 1.2056384 | BM30: IRR | BN30: =BB53 -> 0.062315052
E31: Tenant Leasing Cost | AR31: Swap Breakage Fees - Permanent Loan | AS31: ='Offering Memorandum'!BQ43 -> 28807.114 | BM31: Equity Multiple | BN31: =BN26/-BN27 -> 1.3148364
B32: Capital Stack | D32: ON | E32: =Budget!D26 -> Tenant Capital Reimbursement | F32: 29 | G32: 29 | H32: =IF(AND(H$5>=$F32,H$5<=$G32),$AO32/($G32-$F32+1),0) -> 0 | I32: =IF(AND(I$5>=$F32,I$5<=$G32),$AO32/($G32-$F32+1),0) -> 0 | J32: =IF(AND(J$5>=$F32,J$5<=$G32),$AO32/($G32-$F32+1),0) -> 0 | K32: =IF(AND(K$5>=$F32,K$5<=$G32),$AO32/($G32-$F32+1),0) -> 0 | L32: =IF(AND(L$5>=$F32,L$5<=$G32),$AO32/($G32-$F32+1),0) -> 0 | M32: =IF(AND(M$5>=$F32,M$5<=$G32),$AO32/($G32-$F32+1),0) -> 0 | N32: =IF(AND(N$5>=$F32,N$5<=$G32),$AO32/($G32-$F32+1),0) -> 0 | O32: =IF(AND(O$5>=$F32,O$5<=$G32),$AO32/($G32-$F32+1),0) -> 0 | ... AN32: =IF(AND(AN$5>=$F32,AN$5<=$G32),$AO32/($G32-$F32+1),0) -> 0 | AO32: =Budget!E26 -> 93770 | AP32: =+AO32/SF -> 5 | AR32: Outstanding Rent/TIA Obligations | AS32: =SUM('Offering Memorandum'!EJ14:EL14) -> 179865.22 | AU32: Unlevered IRR | AW32: =AW66 -> 0.028303582 | AY32: =AY66 -> 0.053732307 | AZ32: =AZ66 -> 0.059661846 | BA32: =BA66 -> 0.062768195 | BB32: =BB66 -> 0.064735984 | BC32: =BC66 -> 0.066129806 | BD32: =BD66 -> 0.067192383 | BE32: =BE66 -> 0.068045333 | BF32: =BF66 -> 0.068756329 | BG32: =BG66 -> 0.069366031 | BI32: Levered Development Returns to Equity
B33: Debt | C33: =H79*C9 -> 0.041763574 | D33: OFF | E33: =Budget!D27 -> Leasing Legal | F33: 0 | G33: 0 | H33: =IF(AND(H$5>=$F33,H$5<=$G33),$AO33/($G33-$F33+1),0) -> 3381 | I33: =IF(AND(I$5>=$F33,I$5<=$G33),$AO33/($G33-$F33+1),0) -> 0 | J33: =IF(AND(J$5>=$F33,J$5<=$G33),$AO33/($G33-$F33+1),0) -> 0 | K33: =IF(AND(K$5>=$F33,K$5<=$G33),$AO33/($G33-$F33+1),0) -> 0 | L33: =IF(AND(L$5>=$F33,L$5<=$G33),$AO33/($G33-$F33+1),0) -> 0 | M33: =IF(AND(M$5>=$F33,M$5<=$G33),$AO33/($G33-$F33+1),0) -> 0 | N33: =IF(AND(N$5>=$F33,N$5<=$G33),$AO33/($G33-$F33+1),0) -> 0 | O33: =IF(AND(O$5>=$F33,O$5<=$G33),$AO33/($G33-$F33+1),0) -> 0 | ... AN33: =IF(AND(AN$5>=$F33,AN$5<=$G33),$AO33/($G33-$F33+1),0) -> 0 | AO33: =Budget!E27 -> 3381 | AP33: =+AO33/SF -> 0.18028154 | AR33: Loan Prepayment Fee - Construction Loan | AS33: =Budget!Q41 -> 0 | AU33: Unlevered Equity Multiple | AW33: =(SUM($AW$16:AW16)+AW29)/-AW67 -> 1.0283036 | AY33: =(SUM($AW$16:AY16)+AY29)/-AY67 -> 1.1072167 | AZ33: =(SUM($AW$16:AZ16)+AZ29)/-AZ67 -> 1.1791559 | BA33: =(SUM($AW$16:BA16)+BA29)/-BA67 -> 1.2525096 | BB33: =(SUM($AW$16:BB16)+BB29)/-BB67 -> 1.3273045 | BC33: =(SUM($AW$16:BC16)+BC29)/-BC67 -> 1.4035684 | BD33: =(SUM($AW$16:BD16)+BD29)/-BD67 -> 1.4813292 | BE33: =(SUM($AW$16:BE16)+BE29)/-BE67 -> 1.5606157 | BF33: =(SUM($AW$16:BF16)+BF29)/-BF67 -> 1.6414571 | BG33: =(SUM($AW$16:BG16)+BG29)/-BG67 -> 1.7238833 | BI33: Aspect Health, Inc. House | BJ33: Amount | BK33: $PSF | BM33: Levered Deal Returns to Equity - Year 10
B34: Equity | C34: =(1-C9)*C29 -> 0.039329559 | E34: =Budget!D28 -> Broker Fee | F34: 7 | G34: 7 | H34: =IF(AND(H$5>=$F34,H$5<=$G34),$AO34/($G34-$F34+1),0) -> 0 | I34: =IF(AND(I$5>=$F34,I$5<=$G34),$AO34/($G34-$F34+1),0) -> 0 | J34: =IF(AND(J$5>=$F34,J$5<=$G34),$AO34/($G34-$F34+1),0) -> 0 | K34: =IF(AND(K$5>=$F34,K$5<=$G34),$AO34/($G34-$F34+1),0) -> 0 | L34: =IF(AND(L$5>=$F34,L$5<=$G34),$AO34/($G34-$F34+1),0) -> 0 | M34: =IF(AND(M$5>=$F34,M$5<=$G34),$AO34/($G34-$F34+1),0) -> 0 | N34: =IF(AND(N$5>=$F34,N$5<=$G34),$AO34/($G34-$F34+1),0) -> 0 | O34: =IF(AND(O$5>=$F34,O$5<=$G34),$AO34/($G34-$F34+1),0) -> 0 | ... AN34: =IF(AND(AN$5>=$F34,AN$5<=$G34),$AO34/($G34-$F34+1),0) -> 0 | AO34: =Budget!E28 -> 0 | AP34: =+AO34/SF -> 0 | AR34: Cost of Sale - Exit Year | AS34: =AS35+AS36+AS37 -> 0.0275 | BI34: Total Proceeds | BJ34: =SUMIF(H145:AN145,">0") -> 0 | BK34: =BJ34/SF -> 0 | BM34: Project-Level Returns | BN34: Amount | BO34: $ PSF
B35: Total Capital Stack | C35: =SUM(C33:C34) -> 0.081093133 | AR35: Connecticut State & Municipal Transfer Tax | AS35: 0.015 | AU35: Loan Balance | AW35: =AS42 -> 7715571.4 | AY35: =AW35 -> 7715571.4 | AZ35: =AY35 -> 7715571.4 | BA35: =AZ35 -> 7715571.4 | BB35: =BA35 -> 7715571.4 | BC35: =BB35 -> 7715571.4 | BD35: =BC35 -> 7715571.4 | BE35: =BD35 -> 7715571.4 | BF35: =BE35 -> 7715571.4 | BG35: =BF35 -> 7715571.4 | BI35: Capital Contribution | BJ35: 0 | BK35: =-BJ35/SF -> 0 | BM35: Total Proceeds | BN35: =SUM(BG81:BG90) -> 9524542.5 | BO35: =BN35/$AS$6 -> 507.86725
E36: Tenant Leasing Cost | H36: =+SUBTOTAL(9,H32:H34) -> 3381 | I36: =+SUBTOTAL(9,I32:I34) -> 0 | J36: =+SUBTOTAL(9,J32:J34) -> 0 | K36: =+SUBTOTAL(9,K32:K34) -> 0 | L36: =+SUBTOTAL(9,L32:L34) -> 0 | M36: =+SUBTOTAL(9,M32:M34) -> 0 | N36: =+SUBTOTAL(9,N32:N34) -> 0 | O36: =+SUBTOTAL(9,O32:O34) -> 0 | ... AO36: =+SUBTOTAL(9,AO32:AO34) -> 97151 | AP36: =+AO36/SF -> 5.1802815 | AR36: Broker (Outside) Fee | AS36: 0.01 | AU36: Debt Service | AW36: =AS43 -> 312909.29 | AY36: =AW36 -> 312909.29 | AZ36: =AW36 -> 312909.29 | BA36: =AY36 -> 312909.29 | BB36: =AZ36 -> 312909.29 | BC36: =BA36 -> 312909.29 | BD36: =BB36 -> 312909.29 | BE36: =BC36 -> 312909.29 | BF36: =BD36 -> 312909.29 | BG36: =BE36 -> 312909.29 | BI36: Net Profit | BJ36: =BJ34+BJ35 -> 0 | BK36: =BJ36/SF -> 0 | BM36: Capital Contribution | BN36: =AV44 -> -4154538.5 | BO36: =BN36/-$AS$6 -> 221.52812
AR37: JV Closing Cost's | AS37: 0.0025 | AU37: Debt Coverage Ratio | AW37: =AW12/AW36 -> 2.2133742 | AY37: =AY12/AY36 -> 2.2576417 | AZ37: =AZ12/AZ36 -> 2.3027945 | BA37: =BA12/BA36 -> 2.3488504 | BB37: =BB12/BB36 -> 2.3958274 | BC37: =BC12/BC36 -> 2.4437439 | BD37: =BD12/BD36 -> 2.4926188 | BE37: =BE12/BE36 -> 2.5424712 | BF37: =BF12/BF36 -> 2.5933206 | BG37: =BG12/BG36 -> 2.645187 | BM37: Net Profit | BN37: =BN35+BN36 -> 5370004 | BO37: =BN37/$AS$6 -> 286.33913
E38: Development Financing
E39: =Budget!D21 -> Lender Origination Fee - Permanent Loan | F39: 0 | G39: 0 | H39: =IF(AND(H$5>=$F39,H$5<=$G39),$AO39/($G39-$F39+1),0) -> 32750 | I39: =IF(AND(I$5>=$F39,I$5<=$G39),$AO39/($G39-$F39+1),0) -> 0 | J39: =IF(AND(J$5>=$F39,J$5<=$G39),$AO39/($G39-$F39+1),0) -> 0 | K39: =IF(AND(K$5>=$F39,K$5<=$G39),$AO39/($G39-$F39+1),0) -> 0 | L39: =IF(AND(L$5>=$F39,L$5<=$G39),$AO39/($G39-$F39+1),0) -> 0 | M39: =IF(AND(M$5>=$F39,M$5<=$G39),$AO39/($G39-$F39+1),0) -> 0 | N39: =IF(AND(N$5>=$F39,N$5<=$G39),$AO39/($G39-$F39+1),0) -> 0 | O39: =IF(AND(O$5>=$F39,O$5<=$G39),$AO39/($G39-$F39+1),0) -> 0 | ... AN39: =IF(AND(AN$5>=$F39,AN$5<=$G39),$AO39/($G39-$F39+1),0) -> 0 | AO39: =Budget!E21 -> 32750 | AP39: =+AO39/SF -> 1.7462941 | AR39: Debt | AU39: Net Cash on Sale | AW39: =AW29-AW35 -> 3797919.8 | AY39: =AY29-AY35 -> 4028189.6 | AZ39: =AZ29-AZ35 -> 4161550.9 | BA39: =BA29-BA35 -> 4297289.5 | BB39: =BB29-BB35 -> 4435437.4 | BC39: =BC29-BC35 -> 4576027.6 | BD39: =BD29-BD35 -> 4719093.7 | BE39: =BE29-BE35 -> 4864670.3 | BF39: =BF29-BF35 -> 5012792.5 | BG39: =BG29-BG35 -> 5163496.3 | BM39: IRR | BN39: =BG49 -> 0.11579856
E40: =Budget!D22 -> Lender Origination Fee - Construction Loan | F40: 9 | G40: 9 | H40: =IF(AND(H$5>=$F40,H$5<=$G40),$AO40/($G40-$F40+1),0) -> 0 | I40: =IF(AND(I$5>=$F40,I$5<=$G40),$AO40/($G40-$F40+1),0) -> 0 | J40: =IF(AND(J$5>=$F40,J$5<=$G40),$AO40/($G40-$F40+1),0) -> 0 | K40: =IF(AND(K$5>=$F40,K$5<=$G40),$AO40/($G40-$F40+1),0) -> 0 | L40: =IF(AND(L$5>=$F40,L$5<=$G40),$AO40/($G40-$F40+1),0) -> 0 | M40: =IF(AND(M$5>=$F40,M$5<=$G40),$AO40/($G40-$F40+1),0) -> 0 | N40: =IF(AND(N$5>=$F40,N$5<=$G40),$AO40/($G40-$F40+1),0) -> 0 | O40: =IF(AND(O$5>=$F40,O$5<=$G40),$AO40/($G40-$F40+1),0) -> 0 | ... AN40: =IF(AND(AN$5>=$F40,AN$5<=$G40),$AO40/($G40-$F40+1),0) -> 0 | AO40: =Budget!E22 -> 0 | AP40: =+AO40/SF -> 0 | AR40: LTV | AS40: 0.65 | AU40: Net Gain | AW40: =AW39+$AV$44 -> -356618.7 | AY40: =AY39+$AV$44 -> -126348.88 | AZ40: =AZ39+$AV$44 -> 7012.4786 | BA40: =BA39+$AV$44 -> 142751.02 | BB40: =BB39+$AV$44 -> 280898.92 | BC40: =BC39+$AV$44 -> 421489.1 | BD40: =BD39+$AV$44 -> 564555.26 | BE40: =BE39+$AV$44 -> 710131.82 | BF40: =BF39+$AV$44 -> 858254.02 | BG40: =BG39+$AV$44 -> 1008957.9 | BM40: Equity Multiple | BN40: =BN37/-BN36+1 -> 2.2925633
AR41: Interest Rate | AS41: =(4%/360)*365 -> 0.040555556 | BM41: Avg. Cash-on-Cash | BN41: =BG47 -> 0.10472065
E42: Tenant Leasing Cost | H42: =+SUBTOTAL(9,H39:H40) -> 32750 | I42: =+SUBTOTAL(9,I39:I40) -> 0 | J42: =+SUBTOTAL(9,J39:J40) -> 0 | K42: =+SUBTOTAL(9,K39:K40) -> 0 | L42: =+SUBTOTAL(9,L39:L40) -> 0 | M42: =+SUBTOTAL(9,M39:M40) -> 0 | N42: =+SUBTOTAL(9,N39:N40) -> 0 | O42: =+SUBTOTAL(9,O39:O40) -> 0 | ... AO42: =+SUBTOTAL(9,AO39:AO40) -> 32750 | AP42: =+AO42/SF -> 1.7462941 | AR42: Loan Amount | AS42: =AS8*AS40 -> 7715571.4 | AU42: Net Cash Flow after Debt Service | AW42: =AW16-AW36 -> 379676.05 | AY42: =AY16-AY36 -> 393527.75 | AZ42: =AZ16-AZ36 -> 407656.49 | BA42: =BA16-BA36 -> 422067.81 | BB42: =BB16-BB36 -> 436767.35 | BC42: =BC16-BC36 -> 451760.88 | BD42: =BD16-BD36 -> 467054.29 | BE42: =BE16-BE36 -> 482653.56 | BF42: =BF16-BF36 -> 498564.81 | BG42: =BG16-BG36 -> 514794.3
AR43: Annual Debt Service | AS43: =AS42*AS41 -> 312909.29 | AU43: Asset Management Fees | AW43: =AV44*AS11 -> -10386.346 | AY43: =AW43 -> -10386.346 | AZ43: =AY43 -> -10386.346 | BA43: =AZ43 -> -10386.346 | BB43: =BA43 -> -10386.346 | BC43: =BB43 -> -10386.346 | BD43: =BC43 -> -10386.346 | BE43: =BD43 -> -10386.346 | BF43: =BE43 -> -10386.346 | BG43: =BF43 -> -10386.346 | BM43: Levered Deal Returns to Equity - Year 10
...

Sheet JV Waterfall
B2: ASPECT HEALTH, INC. PROPETY RETURNS - 10 YEAR | R2: ASPECT HEALTH, INC. PROPETY RETURNS - 5 YEAR
B4: Promote Hurdle Method | D4: IRR | R4: Promote Hurdle Method | T4: IRR
B5: Return of Capital | D5: =IF(H14<Equity_Share_GP,"LP 1st","Pari Passu") -> Pari Passu | E5: Yes | R5: Return of Capital | T5: =IF(X14<Equity_Share_GP,"LP 1st","Pari Passu") -> Pari Passu | U5: Yes
B7: Equity Contributions | C7: % | D7: Amount | R7: Equity Contributions | S7: % | T7: Amount
B8: General Partner (GP) | C8: ='Property CF'!AS47 -> 0.1 | D8: =Equity_Share_GP*Total_Equity -> 415453.85 | R8: General Partner (GP) | S8: =Equity_Share_GP -> 0.1 | T8: =Equity_Share_GP*Total_Equity -> 415453.85
B9: Limited Partner (LP) | C9: ='Property CF'!AS48 -> 0.9 | D9: =Total_Equity*Equity_Share_LP -> 3739084.6 | R9: Limited Partner (LP) | S9: =Equity_Share_LP -> 0.9 | T9: =Total_Equity*Equity_Share_LP -> 3739084.6
B10: Total Equity | D10: =-SUMIF(F49:P49,"<0") -> 4154538.5 | R10: Total Equity | T10: =-SUMIF(V49:AA49,"<0") -> 4154538.5
B12: Hurdle Rate Method Used: | C12: =IF(D4="IRR","IRR") -> IRR | F12: Promote Structure Incentive Breakdown | H12: Distribution as % | R12: Hurdle Rate Method Used: | S12: =IF(T4="IRR","IRR") -> IRR | V12: Promote Structure Incentive Breakdown | X12: Distribution as %
B13: =IF(D4="Equity Multiple","Partnership Distribution Assumptions (Equity Multiple Hurdles)",IF(D4="IRR","Partnership Distribution Assumptions (IRR Hurdles)","Partnership Distribution Assumptions (Max of IRR or Emx Hurdles)")) -> Partnership Distribution Assumptions (IRR Hurdles) | H13: GP % | I13: LP % | R13: =IF(T4="Equity Multiple","Partnership Distribution Assumptions (Equity Multiple Hurdles)",IF(T4="IRR","Partnership Distribution Assumptions (IRR Hurdles)","Partnership Distribution Assumptions (Max of IRR or Emx Hurdles)")) -> Partnership Distribution Assumptions (IRR Hurdles) | X13: GP % | Y13: LP %
B14: Tier 1 (Pref + Return of Capital) | C14: Equity Multiple | D14: IRR | E14: =IF($D$4="Equity Multiple",C15,D15) -> 0 | F14: GP Promote | H14: =Equity_Share_GP -> 0.1 | I14: =1-H14 -> 0.9 | R14: Tier 1 (Pref + Return of Capital) | S14: Equity Multiple | T14: IRR | U14: =IF($T$4="Equity Multiple",S15,T15) -> 0 | V14: GP Promote | X14: =Equity_Share_GP -> 0.1 | Y14: =1-X14 -> 0.9
B15: Tier 2 (Promote) | C15: 2 | D15: 0 | E15: =IF($D$4="Equity Multiple",C16,D16) -> 0 | F15: 0 | H15: =H14+F15 -> 0.1 | I15: =1-H15 -> 0.9 | R15: Tier 2 (Promote) | S15: 2 | T15: 0 | U15: =IF($T$4="Equity Multiple",S16,T16) -> 0 | V15: 0 | X15: =X14+V15 -> 0.1 | Y15: =1-X15 -> 0.9
B16: Tier 3 (Promote) | C16: 2.5 | D16: 0 | E16: =IF($D$4="Equity Multiple",C17,D17) -> 0 | F16: 0 | H16: =F16+H14 -> 0.1 | I16: =1-H16 -> 0.9 | R16: Tier 3 (Promote) | S16: 2.5 | T16: 0 | U16: =IF($T$4="Equity Multiple",S17,T17) -> 0 | V16: 0 | X16: =V16+X14 -> 0.1 | Y16: =1-X16 -> 0.9
B17: Tier 4 (Promote) | C17: 3 | D17: 0 | F17: 0 | H17: =H14+F17 -> 0.1 | I17: =1-H17 -> 0.9 | R17: Tier 4 (Promote) | S17: 3 | T17: 0 | V17: 0 | X17: =X14+V17 -> 0.1 | Y17: =1-X17 -> 0.9
B19: Summary of Partnership-Level Returns | F19: 0 | G19: =IF(G45="","",F19+1) -> 1 | H19: =IF(H45="","",G19+1) -> 2 | I19: =IF(I45="","",H19+1) -> 3 | J19: =IF(J45="","",I19+1) -> 4 | K19: =IF(K45="","",J19+1) -> 5 | L19: =IF(L45="","",K19+1) -> 6 | M19: =IF(M45="","",L19+1) -> 7 | N19: =IF(N45="","",M19+1) -> 8 | ... P19: =IF(P45="","",O19+1) -> 10 | R19: Summary of Partnership-Level Returns | V19: 0 | W19: =IF(W45="","",V19+1) -> 1 | X19: =IF(X45="","",W19+1) -> 2 | Y19: =IF(Y45="","",X19+1) -> 3 | Z19: =IF(Z45="","",Y19+1) -> 4 | AA19: =IF(AA45="","",Z19+1) -> 5
B20: Limited Partner (LP) Returns | R20: Limited Partner (LP) Returns
C21: Check | S21: Check
B22: Preferred Return | C22: =IF(ROUND(D22,0)=ROUND(SUM(F22:P22),0),"OK","ERROR") -> OK | D22: =(C12="IRR")*(SUM(F94:P94)-D23) -> 4.6566129e-10 | F22: =IF(F19="","",MIN($D22-SUM($E22:E22),F25-F23)) -> 0 | G22: =IF(G19="","",MIN($D22-SUM($E22:F22),G25-G23)) -> 0 | H22: =IF(H19="","",MIN($D22-SUM($E22:G22),H25-H23)) -> 0 | I22: =IF(I19="","",MIN($D22-SUM($E22:H22),I25-I23)) -> 0 | J22: =IF(J19="","",MIN($D22-SUM($E22:I22),J25-J23)) -> 0 | K22: =IF(K19="","",MIN($D22-SUM($E22:J22),K25-K23)) -> 0 | L22: =IF(L19="","",MIN($D22-SUM($E22:K22),L25-L23)) -> 0 | M22: =IF(M19="","",MIN($D22-SUM($E22:L22),M25-M23)) -> 0 | ... P22: =IF(P19="","",MIN($D22-SUM($E22:O22),P25-P23)) -> 4.6566129e-10 | R22: Preferred Return | S22: =IF(ROUND(T22,0)=ROUND(SUM(V22:AA22),0),"OK","ERROR") -> OK | T22: =(S12="IRR")*(SUM(V94:AA94)-T23) -> 4.6566129e-10 | V22: =IF(V19="","",MIN($T22-SUM($U22:U22),V25-V23)) -> 0 | W22: =IF(W19="","",MIN($T22-SUM($U22:V22),W25-W23)) -> 0 | X22: =IF(X19="","",MIN($T22-SUM($U22:W22),X25-X23)) -> 0 | Y22: =IF(Y19="","",MIN($T22-SUM($U22:X22),Y25-Y23)) -> 0 | Z22: =IF(Z19="","",MIN($T22-SUM($U22:Y22),Z25-Z23)) -> 0 | AA22: =IF(AA19="","",MIN($T22-SUM($U22:Z22),AA25-AA23)) -> 4.6566129e-10
B23: Return of Capital | C23: =IF(ROUND(D23,0)=ROUND(SUM(F23:P23),0),"OK","ERROR") -> OK | D23: =MIN(D26,D25) -> 3739084.6 | F23: =IF(F19="","",MIN($D23-SUM($E23:E23),F25)) -> 0 | G23: =IF(G19="","",MIN($D23-SUM($E23:F23),G25)) -> 332360.73 | H23: =IF(H19="","",MIN($D23-SUM($E23:G23),H25)) -> 344827.26 | I23: =IF(I19="","",MIN($D23-SUM($E23:H23),I25)) -> 357543.13 | J23: =IF(J19="","",MIN($D23-SUM($E23:I23),J25)) -> 370513.32 | K23: =IF(K19="","",MIN($D23-SUM($E23:J23),K25)) -> 383742.9 | L23: =IF(L19="","",MIN($D23-SUM($E23:K23),L25)) -> 397237.08 | M23: =IF(M19="","",MIN($D23-SUM($E23:L23),M25)) -> 411001.15 | ... P23: =IF(P19="","",MIN($D23-SUM($E23:O23),P25)) -> 277457.93 | R23: Return of Capital | S23: =IF(ROUND(T23,0)=ROUND(SUM(V23:AA23),0),"OK","ERROR") -> OK | T23: =MIN(T26,T25) -> 3739084.6 | V23: =IF(V19="","",MIN($T23-SUM($U23:U23),V25)) -> 0 | W23: =IF(W19="","",MIN($T23-SUM($U23:V23),W25)) -> 332360.73 | X23: =IF(X19="","",MIN($T23-SUM($U23:W23),X25)) -> 344827.26 | Y23: =IF(Y19="","",MIN($T23-SUM($U23:X23),Y25)) -> 357543.13 | Z23: =IF(Z19="","",MIN($T23-SUM($U23:Y23),Z25)) -> 370513.32 | AA23: =IF(AA19="","",MIN($T23-SUM($U23:Z23),AA25)) -> 2333840.2
B24: Excess Cash Flow | C24: =IF(ROUND(D24,0)=ROUND(SUM(F24:P24),0),"OK","ERROR") -> OK | D24: =D25-D23-D22 -> 4823655.9 | F24: =IF(F19="","",F25-F23-F22) -> 0 | G24: =IF(G19="","",G25-G23-G22) -> 0 | H24: =IF(H19="","",H25-H23-H22) -> 0 | I24: =IF(I19="","",I25-I23-I22) -> 0 | J24: =IF(J19="","",J25-J23-J22) -> 0 | K24: =IF(K19="","",K25-K23-K22) -> 0 | L24: =IF(L19="","",L25-L23-L22) -> 0 | M24: =IF(M19="","",M25-M23-M22) -> 0 | ... P24: =IF(P19="","",P25-P23-P22) -> 4823655.9 | R24: Excess Cash Flow | S24: =IF(ROUND(T24,0)=ROUND(SUM(V24:AA24),0),"OK","ERROR") -> OK | T24: =T25-T23-T22 -> 2041796.4 | V24: =IF(V19="","",V25-V23-V22) -> 0 | W24: =IF(W19="","",W25-W23-W22) -> 0 | X24: =IF(X19="","",X25-X23-X22) -> 0 | Y24: =IF(Y19="","",Y25-Y23-Y22) -> 0 | Z24: =IF(Z19="","",Z25-Z23-Z22) -> 0 | AA24: =IF(AA19="","",AA25-AA23-AA22) -> 2041796.4
B25: Total LP Distributions | D25: =SUM(F25:P25) -> 8562740.5 | F25: =IF(F$19="","",($C$12="IRR")*F65) -> 0 | G25: =IF(G$19="","",($C$12="IRR")*G65) -> 332360.73 | H25: =IF(H$19="","",($C$12="IRR")*H65) -> 344827.26 | I25: =IF(I$19="","",($C$12="IRR")*I65) -> 357543.13 | J25: =IF(J$19="","",($C$12="IRR")*J65) -> 370513.32 | K25: =IF(K$19="","",($C$12="IRR")*K65) -> 383742.9 | L25: =IF(L$19="","",($C$12="IRR")*L65) -> 397237.08 | M25: =IF(M$19="","",($C$12="IRR")*M65) -> 411001.15 | ... P25: =IF(P$19="","",($C$12="IRR")*P65) -> 5101113.8 | R25: Total LP Distributions | T25: =SUM(V25:AA25) -> 5780881 | V25: =IF(V$19="","",($S$12="IRR")*V65) -> 0 | W25: =IF(W$19="","",($S$12="IRR")*W65) -> 332360.73 | X25: =IF(X$19="","",($S$12="IRR")*X65) -> 344827.26 | Y25: =IF(Y$19="","",($S$12="IRR")*Y65) -> 357543.13 | Z25: =IF(Z$19="","",($S$12="IRR")*Z65) -> 370513.32 | AA25: =IF(AA$19="","",($S$12="IRR")*AA65) -> 4375636.5
B26: Total LP Contributions | D26: =SUM(F26:P26) -> 3739084.6 | F26: =F93 -> 3739084.6 | G26: =G93 -> 0 | H26: =H93 -> 0 | I26: =I93 -> 0 | J26: =J93 -> 0 | K26: =K93 -> 0 | L26: =L93 -> 0 | M26: =M93 -> 0 | ... P26: =P93 -> 0 | R26: Total LP Contributions | T26: =SUM(V26:AA26) -> 3739084.6 | V26: =V93 -> 3739084.6 | W26: =W93 -> 0 | X26: =X93 -> 0 | Y26: =Y93 -> 0 | Z26: =Z93 -> 0 | AA26: =AA93 -> 0
B27: Total LP Profit | D27: =D25-D26 -> 4823655.9 | R27: Total LP Profit | T27: =T25-T26 -> 2041796.4
B28: LP IRR | D28: =IRR(F28:P28) -> 0.11566557 | F28: =IF(F19="","",(-F26)+F25) -> -3739084.6 | G28: =IF(G19="","",(-G26)+G25) -> 332360.73 | H28: =IF(H19="","",(-H26)+H25) -> 344827.26 | I28: =IF(I19="","",(-I26)+I25) -> 357543.13 | J28: =IF(J19="","",(-J26)+J25) -> 370513.32 | K28: =IF(K19="","",(-K26)+K25) -> 383742.9 | L28: =IF(L19="","",(-L26)+L25) -> 397237.08 | M28: =IF(M19="","",(-M26)+M25) -> 411001.15 | ... P28: =IF(P19="","",(-P26)+P25) -> 5101113.8 | R28: LP IRR | T28: =IRR(V28:AA28) -> 0.10594725 | V28: =IF(V19="","",(-V26)+V25) -> -3739084.6 | W28: =IF(W19="","",(-W26)+W25) -> 332360.73 | X28: =IF(X19="","",(-X26)+X25) -> 344827.26 | Y28: =IF(Y19="","",(-Y26)+Y25) -> 357543.13 | Z28: =IF(Z19="","",(-Z26)+Z25) -> 370513.32 | AA28: =IF(AA19="","",(-AA26)+AA25) -> 4375636.5
B29: LP Equity Multiple | D29: =D25/D26 -> 2.2900633 | R29: LP Equity Multiple | T29: =T25/T26 -> 1.5460685
B31: GP Returns | R31: GP Returns
B32: Preferred Return | C32: =IF(ROUND(D32,0)=ROUND(SUM(F32:P32),0),"OK","ERROR") -> OK | D32: =(C12="IRR")*(SUM(F102:P102)-D33) -> 0 | F32: =IF(F19="","",MIN($D32-SUM($E32:E32),F36-F33)) -> 0 | G32: =IF(G19="","",MIN($D32-SUM($E32:F32),G36-G33)) -> 0 | H32: =IF(H19="","",MIN($D32-SUM($E32:G32),H36-H33)) -> 0 | I32: =IF(I19="","",MIN($D32-SUM($E32:H32),I36-I33)) -> 0 | J32: =IF(J19="","",MIN($D32-SUM($E32:I32),J36-J33)) -> 0 | K32: =IF(K19="","",MIN($D32-SUM($E32:J32),K36-K33)) -> 0 | L32: =IF(L19="","",MIN($D32-SUM($E32:K32),L36-L33)) -> 0 | M32: =IF(M19="","",MIN($D32-SUM($E32:L32),M36-M33)) -> 0 | ... P32: =IF(P19="","",MIN($D32-SUM($E32:O32),P36-P33)) -> 0 | R32: Preferred Return | S32: =IF(ROUND(T32,0)=ROUND(SUM(V32:AA32),0),"OK","ERROR") -> OK | T32: =(S12="IRR")*(SUM(V102:AA102)-T33) -> 0 | V32: =IF(V19="","",MIN($T32-SUM($U32:U32),V36-V33)) -> 0 | W32: =IF(W19="","",MIN($T32-SUM($U32:V32),W36-W33)) -> 0 | X32: =IF(X19="","",MIN($T32-SUM($U32:W32),X36-X33)) -> 0 | Y32: =IF(Y19="","",MIN($T32-SUM($U32:X32),Y36-Y33)) -> 0 | Z32: =IF(Z19="","",MIN($T32-SUM($U32:Y32),Z36-Z33)) -> 0 | AA32: =IF(AA19="","",MIN($T32-SUM($U32:Z32),AA36-AA33)) -> 0
B33: Return of Capital | C33: =IF(ROUND(D33,0)=ROUND(SUM(F33:P33),0),"OK","ERROR") -> OK | D33: =MIN(D36,D38) -> 415453.85 | F33: =IF(F19="","",MIN($D33-SUM($E33:E33),F36)) -> 0 | G33: =IF(G19="","",MIN($D33-SUM($E33:F33),G36)) -> 36928.97 | H33: =IF(H19="","",MIN($D33-SUM($E33:G33),H36)) -> 38314.141 | I33: =IF(I19="","",MIN($D33-SUM($E33:H33),I36)) -> 39727.015 | J33: =IF(J19="","",MIN($D33-SUM($E33:I33),J36)) -> 41168.146 | K33: =IF(K19="","",MIN($D33-SUM($E33:J33),K36)) -> 42638.1 | L33: =IF(L19="","",MIN($D33-SUM($E33:K33),L36)) -> 44137.454 | M33: =IF(M19="","",MIN($D33-SUM($E33:L33),M36)) -> 45666.794 | ... P33: =IF(P19="","",MIN($D33-SUM($E33:O33),P36)) -> 30828.658 | R33: Return of Capital | S33: =IF(ROUND(T33,0)=ROUND(SUM(V33:AA33),0),"OK","ERROR") -> OK | T33: =MIN(T36,T38) -> 415453.85 | V33: =IF(V19="","",MIN($T33-SUM($U33:U33),V36)) -> 0 | W33: =IF(W19="","",MIN($T33-SUM($U33:V33),W36)) -> 36928.97 | X33: =IF(X19="","",MIN($T33-SUM($U33:W33),X36)) -> 38314.141 | Y33: =IF(Y19="","",MIN($T33-SUM($U33:X33),Y36)) -> 39727.015 | Z33: =IF(Z19="","",MIN($T33-SUM($U33:Y33),Z36)) -> 41168.146 | AA33: =IF(AA19="","",MIN($T33-SUM($U33:Z33),AA36)) -> 259315.57
B34: Promote | C34: =IF(ROUND(D34,0)=ROUND(SUM(F34:P34),0),"OK","ERROR") -> OK | D34: =D36-D33-D35-D32 -> 2.3283064e-10 | F34: =IF(F19="","",F36-F35-F33-F32) -> 0 | G34: =IF(G19="","",G36-G35-G33-G32) -> 0 | H34: =IF(H19="","",H36-H35-H33-H32) -> 0 | I34: =IF(I19="","",I36-I35-I33-I32) -> 0 | J34: =IF(J19="","",J36-J35-J33-J32) -> 0 | K34: =IF(K19="","",K36-K35-K33-K32) -> 0 | L34: =IF(L19="","",L36-L35-L33-L32) -> 0 | M34: =IF(M19="","",M36-M35-M33-M32) -> 0 | ... P34: =IF(P19="","",P36-P35-P33-P32) -> 1.7462298e-10 | R34: Promote | S34: =IF(ROUND(T34,0)=ROUND(SUM(V34:AA34),0),"OK","ERROR") -> OK | T34: =T36-T33-T35-T32 -> -8.7311491e-11 | V34: =IF(V19="","",V36-V35-V33-V32) -> 0 | W34: =IF(W19="","",W36-W35-W33-W32) -> 0 | X34: =IF(X19="","",X36-X35-X33-X32) -> 0 | Y34: =IF(Y19="","",Y36-Y35-Y33-Y32) -> 0 | Z34: =IF(Z19="","",Z36-Z35-Z33-Z32) -> 0 | AA34: =IF(AA19="","",AA36-AA35-AA33-AA32) -> -8.7311491e-11
B35: Excess Cash Flow | C35: =IF(ROUND(D35,0)=ROUND(SUM(F35:P35),0),"OK","ERROR") -> OK | D35: =D24/Equity_Share_LP*Equity_Share_GP -> 535961.77 | F35: =IF(F19="","",F24/Equity_Share_LP*Equity_Share_GP) -> 0 | G35: =IF(G19="","",G24/Equity_Share_LP*Equity_Share_GP) -> 0 | H35: =IF(H19="","",H24/Equity_Share_LP*Equity_Share_GP) -> 0 | I35: =IF(I19="","",I24/Equity_Share_LP*Equity_Share_GP) -> 0 | J35: =IF(J19="","",J24/Equity_Share_LP*Equity_Share_GP) -> 0 | K35: =IF(K19="","",K24/Equity_Share_LP*Equity_Share_GP) -> 0 | L35: =IF(L19="","",L24/Equity_Share_LP*Equity_Share_GP) -> 0 | M35: =IF(M19="","",M24/Equity_Share_LP*Equity_Share_GP) -> 0 | ... P35: =IF(P19="","",P24/Equity_Share_LP*Equity_Share_GP) -> 535961.77 | R35: Excess Cash Flow | S35: =IF(ROUND(T35,0)=ROUND(SUM(V35:AA35),0),"OK","ERROR") -> OK | T35: =T24/Equity_Share_LP*Equity_Share_GP -> 226866.26 | V35: =IF(V19="","",V24/Equity_Share_LP*Equity_Share_GP) -> 0 | W35: =IF(W19="","",W24/Equity_Share_LP*Equity_Share_GP) -> 0 | X35: =IF(X19="","",X24/Equity_Share_LP*Equity_Share_GP) -> 0 | Y35: =IF(Y19="","",Y24/Equity_Share_LP*Equity_Share_GP) -> 0 | Z35: =IF(Z19="","",Z24/Equity_Share_LP*Equity_Share_GP) -> 0 | AA35: =IF(AA19="","",AA24/Equity_Share_LP*Equity_Share_GP) -> 226866.26
