Workbook
Name Aspect_Equity_Interest: Summary!$C$22
Name Asset_Management_Fee: Summary!$C$10
Name Capital_Reserves__RSF: Summary!$C$11
Name Cost_of_Sale__Transfer_Tax___Broker_Fee: 'Portfolio-Level CF'!$AC$52
Name Equity_Share_GP: 'JV Waterfall'!$C$8
Name Equity_Share_LP: 'JV Waterfall'!$C$9
Name Interest_Rate: Summary!$C$16
Name LTC: Summary!$C$15
Name Preferred_Return: 'JV Waterfall'!$E$14
Name Total_Equity: 'JV Waterfall'!$D$10
Name Welltower_Equity_Interest: Summary!$C$23

Sheet Summary
B1: Tucker017!
B2: Assumptions | E2: Purchase Price Summary
B3: Sale | E3: Property Address | F3: RSF | G3: % of RSF | H3: Year 1 NOI | I3: % of NOI | J3: Purchase Price | K3: % of Purchase | L3: Cap Rate
B4: Purchase Price | C4: =Summary!J10 -> 99250000 | E4: 131 Kent Road, New Milford, CT 06776 | F4: ='Rent Roll'!C17 -> 29341 | G4: =F4/$F$10 -> 0.14865009 | H4: ='Portfolio-Level CF'!AC16 -> 776823 | I4: =H4/$H$10 -> 0.152728 | J4: 13296853 | K4: =J4/$J$10 -> 0.13397333 | L4: =H4/J4 -> 0.058421568
B5: Earnouts | C5: =C39 -> 2284000 | E5: 164 Mount Pleasant Road, Newtown, CT 06470 | F5: ='Rent Roll'!C30 -> 25984 | G5: =F5/$F$10 -> 0.13164254 | H5: ='Portfolio-Level CF'!AC22 -> 421291 | I5: =H5/$H$10 -> 0.082828302 | J5: 10215862 | K5: =J5/$J$10 -> 0.1029306 | L5: =H5/J5 -> 0.041238909
B6: TI/LC | C6: =C56+C61 -> 1270966.5 | E6: 170 Mount Pleasant Road, Newtown, CT 06470 | F6: ='Rent Roll'!C42 -> 30000 | G6: =F6/$F$10 -> 0.15198877 | H6: ='Portfolio-Level CF'!AC28 -> 638299 | I6: =H6/$H$10 -> 0.12549336 | J6: 11049286 | K6: =J6/$J$10 -> 0.11132782 | L6: =H6/J6 -> 0.057768347
B7: Closing Costs | C7: =C49 -> 935471 | E7: 2 Riverview Drive, Danbury, CT 06810 | F7: ='Rent Roll'!C55 -> 43201 | G7: =F7/$F$10 -> 0.2188689 | H7: ='Portfolio-Level CF'!AC34 -> 1354228 | I7: =H7/$H$10 -> 0.26624923 | J7: 26594452 | K7: =J7/$J$10 -> 0.26795418 | L7: =H7/J7 -> 0.050921448
B8: Lease Legal Costs - DaVita | C8: =C66 -> 10000 | E8: 226 White Street, Danbury, CT 06810 | F8: ='Rent Roll'!C64 -> 26150 | G8: =F8/$F$10 -> 0.13248355 | H8: ='Portfolio-Level CF'!AC40 -> 584129 | I8: =H8/$H$10 -> 0.11484322 | J8: 11256765 | K8: =J8/$J$10 -> 0.11341829 | L8: =H8/J8 -> 0.051891374
B9: Total Development Cost | C9: =C4+SUM(C5:C8) -> 1.0375044e+08 | E9: 40 Old Ridgebury Road, Danbury, CT 06810 | F9: ='Rent Roll'!C75 -> 42707 | G9: =F9/$F$10 -> 0.21636615 | H9: ='Portfolio-Level CF'!AC46 -> 1311547 | I9: =H9/$H$10 -> 0.2578579 | J9: 26836782 | K9: =J9/$J$10 -> 0.27039579 | L9: =H9/J9 -> 0.048871247
B10: Asset Management Fee % | C10: 0.0025 | E10: Total | F10: =SUM(F4:F9) -> 197383 | G10: =SUM(G4:G9) -> 1 | H10: =SUM(H4:H9) -> 5086317 | I10: =SUM(I4:I9) -> 1 | J10: =SUM(J4:J9) -> 99250000 | K10: =SUM(K4:K9) -> 1 | L10: =H10/J10 -> 0.051247526
B11: Capital Reserves (RSF) | C11: 0.5 | J11: =J10+39700000+12000000+7000000 -> 157950000
B12: Portfolio Size (RSF) | C12: =Summary!F10 -> 197383 | E12: Total Development Cost Summary
E13: Property Address | F13: Pro-Rata Closing Costs | G13: Tenant Improvments | H13: Leasing Commissions | I13: Earnouts | J13: Total Cost | K13: % of Total Cost | L13: Cap Rate
B14: Debt | E14: 131 Kent Road, New Milford, CT 06776 | F14: =$C$7*(J4/$J$10) -> 125328.16 | G14: 0 | H14: 0 | I14: 0 | J14: =J4+SUM(F14:I14) -> 13422181 | K14: =J14/$J$20 -> 0.12936988 | L14: =H4/J14 -> 0.057876063
B15: LTC | C15: 0.65 | E15: 164 Mount Pleasant Road, Newtown, CT 06470 | F15: =$C$7*(J5/$J$10) -> 96288.59 | G15: =C54+C55 -> 565220 | H15: =C61 -> 74471.53 | I15: 0 | J15: =J5+SUM(F15:I15)+C8 -> 10961842 | K15: =J15/$J$20 -> 0.10565586 | L15: =H5/J15 -> 0.038432501
B16: Interest Rate | C16: =(4%*(365/360)) -> 0.040555556 | E16: 170 Mount Pleasant Road, Newtown, CT 06470 | F16: =$C$7*(J6/$J$10) -> 104143.95 | G16: =C52+C53 -> 631275 | H16: 0 | I16: =C39 -> 2284000 | J16: =J6+SUM(F16:I16) -> 14068705 | K16: =J16/$J$20 -> 0.1356014 | L16: =H6/J16 -> 0.045370132
B17: Loan Amount | C17: =C9*C15 -> 67437784 | E17: 2 Riverview Drive, Danbury, CT 06810 | F17: =$C$7*(J7/$J$10) -> 250663.36 | G17: 0 | H17: 0 | I17: 0 | J17: =J7+SUM(F17:I17) -> 26845115 | K17: =J17/$J$20 -> 0.25874701 | L17: =H7/J17 -> 0.050445974
B18: Annual Debt Service | C18: =C17*((C16/360)*365) -> 2772962.6 | E18: 226 White Street, Danbury, CT 06810 | F18: =$C$7*(J8/$J$10) -> 106099.52 | G18: 0 | H18: 0 | I18: 0 | J18: =J8+SUM(F18:I18) -> 11362865 | K18: =J18/$J$20 -> 0.10952112 | L18: =H8/J18 -> 0.051406844
E19: 40 Old Ridgebury Road, Danbury, CT 06810 | F19: =$C$7*(J9/$J$10) -> 252947.42 | G19: 0 | H19: 0 | I19: 0 | J19: =J9+SUM(F19:I19) -> 27089729 | K19: =J19/$J$20 -> 0.26110472 | L19: =H9/J19 -> 0.048414917
B20: Equity | E20: Total | F20: =SUM(F14:F19) -> 935471 | G20: =SUM(G14:G19) -> 1196495 | H20: =SUM(H14:H19) -> 74471.53 | I20: =SUM(I14:I19) -> 2284000 | J20: =SUM(J14:J19) -> 1.0375044e+08 | K20: =SUM(K14:K19) -> 1 | L20: =H10/J20 -> 0.049024535
B21: Required Initial Common Capital Contributions | C21: =C9-C17 -> 36312653
B22: Aspect Equity Interest % | C22: 0.05 | E22: Common Equity & Preferred Equity Splits
B23: Welltower Equity Interest % | C23: 0.95 | E23: Property Address | F23: Aspect Common Interest | G23: Welltower Common Interest | H23: Initial Common Capital | I23: Initial Preferred Capital | J23: Welltower Total Interest | K23: Aspect Total Interest | L23: Total Capital
E24: =E4 -> 131 Kent Road, New Milford, CT 06776 | F24: =H24*Summary!$C$22 -> 234888.17 | G24: =H24*Summary!$C$23 -> 4462875.2 | H24: =K14*Summary!$C$21 -> 4697763.4 | I24: =Summary!$C$17*K14 -> 8724417.8 | J24: =I24+G24 -> 13187293 | K24: =F24 -> 234888.17 | L24: =I24+H24 -> 13422181
B25: Aspect Equity Interest | C25: =Summary!F30 -> 1815632.7 | E25: =E5 -> 164 Mount Pleasant Road, Newtown, CT 06470 | F25: =H25*Summary!$C$22 -> 191832.23 | G25: =H25*Summary!$C$23 -> 3644812.5 | H25: =K15*Summary!$C$21 -> 3836644.7 | I25: =Summary!$C$17*K15 -> 7125197.3 | J25: =I25+G25 -> 10770010 | K25: =F25 -> 191832.23 | L25: =I25+H25 -> 10961842
B26: Welltower Equity Interest | C26: =Summary!G30 -> 34497020 | E26: =E6 -> 170 Mount Pleasant Road, Newtown, CT 06470 | F26: =H26*Summary!$C$22 -> 246202.34 | G26: =H26*Summary!$C$23 -> 4677844.4 | H26: =K16*Summary!$C$21 -> 4924046.8 | I26: =Summary!$C$17*K16 -> 9144658.3 | J26: =I26+G26 -> 13822503 | K26: =F26 -> 246202.34 | L26: =I26+H26 -> 14068705
B27: Total Equity Interest | C27: =C25+C26 -> 36312653 | E27: =E7 -> 2 Riverview Drive, Danbury, CT 06810 | F27: =H27*Summary!$C$22 -> 469789.52 | G27: =H27*Summary!$C$23 -> 8926000.9 | H27: =K17*Summary!$C$21 -> 9395790.4 | I27: =Summary!$C$17*K17 -> 17449325 | J27: =I27+G27 -> 26375326 | K27: =F27 -> 469789.52 | L27: =I27+H27 -> 26845115
E28: =E8 -> 226 White Street, Danbury, CT 06810 | F28: =H28*Summary!$C$22 -> 198850.13 | G28: =H28*Summary!$C$23 -> 3778152.5 | H28: =K18*Summary!$C$21 -> 3977002.6 | I28: =Summary!$C$17*K18 -> 7385861.9 | J28: =I28+G28 -> 11164014 | K28: =F28 -> 198850.13 | L28: =I28+H28 -> 11362865
B29: JV Ownership Interest | E29: =E9 -> 40 Old Ridgebury Road, Danbury, CT 06810 | F29: =H29*Summary!$C$22 -> 474070.26 | G29: =H29*Summary!$C$23 -> 9007335 | H29: =K19*Summary!$C$21 -> 9481405.3 | I29: =Summary!$C$17*K19 -> 17608324 | J29: =I29+G29 -> 26615659 | K29: =F29 -> 474070.26 | L29: =I29+H29 -> 27089729
B30: =B9 -> Total Development Cost | C30: =C9 -> 1.0375044e+08 | E30: Total | F30: =SUM(F24:F29) -> 1815632.7 | G30: =SUM(G24:G29) -> 34497020 | H30: =SUM(H24:H29) -> 36312653 | I30: =SUM(I24:I29) -> 67437784 | J30: =SUM(J24:J29) -> 1.019348e+08 | K30: =SUM(K24:K29) -> 1815632.7 | L30: =I30+H30 -> 1.0375044e+08
B31: Aspect Total Interest | C31: =Summary!F30/C30 -> 0.0175
B32: Welltower Total Interest | C32: =Summary!J30/C30 -> 0.9825 | E32: Property Valuation & Leveraged Returns by Property - Year 10 | N32: Leveraged Returns to Equity - Year 10 | R32: Leveraged Returns to Equity - Year 10
E33: Property Address | F33: Year 10 NOI | G33: Year 10 Net Sale Price | H33: Net Gain on Sale | I33: Levered IRR | J33: Equity Multiple | K33: Average Cash on Cash | L33: Cap Spread | N33: Leveraged Project Returns | O33: Amount | P33: $ PSF | R33: Aspect Health Inc. Returns | S33: Amount | T33: $ PSF
E34: =E24 -> 131 Kent Road, New Milford, CT 06776 | F34: ='Property-Level CF'!M10 -> 884835 | G34: =(F34/L4)*(1-'Portfolio-Level CF'!$AC$52) -> 14562582 | H34: =G34-J4 -> 1265728.7 | I34: ='Property-Level CF'!M44 -> 0.080202328 | J34: ='Property-Level CF'!M45 -> 1.8775317 | K34: ='Property-Level CF'!M42 -> 0.063477776 | L34: ='Property-Level CF'!M20 -> 0.0075017712 | N34: Total Proceeds | O34: =SUM('Portfolio-Level CF'!D39:M39) -> 81273719 | P34: =O34/$C$12 -> 411.75643 | R34: Total GP Distributions | S34: =SUM('Portfolio-Level CF'!D52:M52)+'Portfolio-Level CF'!M66-'Portfolio-Level CF'!M54 -> 4063685.9 | T34: =S34/$C$12 -> 20.587821
B35: Additional Development Costs | E35: =E25 -> 164 Mount Pleasant Road, Newtown, CT 06470 | F35: ='Property-Level CF'!AL10 -> 791022 | G35: =(F35/L5)*(1-'Portfolio-Level CF'!$AC$52) -> 18442962 | H35: =G35-J5 -> 8227100.6 | I35: ='Property-Level CF'!AL44 -> 0.13599865 | J35: ='Property-Level CF'!AL45 -> 2.8608086 | K35: ='Property-Level CF'!AL42 -> 0.097761736 | L35: ='Property-Level CF'!AL20 -> 0.019161412 | N35: Capital Contribution | O35: ='Portfolio-Level CF'!C39 -> -36312653 | P35: =-O35/$C$12 -> 183.97052 | R35: Total Asset Management Fee's | S35: =SUM('Portfolio-Level CF'!D53:M53) -> 907816.33 | T35: =S35/$C$12 -> 4.599263
B36: Earnouts | E36: =E26 -> 170 Mount Pleasant Road, Newtown, CT 06470 | F36: ='Property-Level CF'!BK10 -> 987095 | G36: =(F36/L6)*(1-'Portfolio-Level CF'!$AC$52) -> 16429271 | H36: =G36-J6 -> 5379985 | I36: ='Property-Level CF'!BK44 -> 0.13334286 | J36: ='Property-Level CF'!BK45 -> 2.7893739 | K36: ='Property-Level CF'!BK42 -> 0.1009794 | L36: ='Property-Level CF'!BK20 -> 0.017162463 | N36: Net Profit | O36: =O34+O35 -> 44961066 | P36: =O36/$C$12 -> 227.78591 | R36: Capital Contribution | S36: ='Portfolio-Level CF'!C54 -> -1815632.7 | T36: =-S36/$C$12 -> 9.198526
B37: Women's Health | C37: 1362000 | E37: =E27 -> 2 Riverview Drive, Danbury, CT 06810 | F37: ='Property-Level CF'!CJ10 -> 1584598 | G37: =(F37/L7)*(1-'Portfolio-Level CF'!$AC$52) -> 29920417 | H37: =G37-J7 -> 3325965.5 | I37: ='Property-Level CF'!CJ44 -> 0.094007475 | J37: ='Property-Level CF'!CJ45 -> 2.1008023 | K37: ='Property-Level CF'!CJ42 -> 0.077349589 | L37: ='Property-Level CF'!CJ20 -> 0.0081059759 | R37: Net GP Profit | S37: =S34+S35+S36 -> 3155869.6 | T37: =S37/$C$12 -> 15.988558
B38: AccessPT | C38: 922000 | E38: =E28 -> 226 White Street, Danbury, CT 06810 | F38: ='Property-Level CF'!DI10 -> 698088 | G38: =(F38/L8)*(1-'Portfolio-Level CF'!$AC$52) -> 12934936 | H38: =G38-J8 -> 1678171.3 | I38: ='Property-Level CF'!DI44 -> 0.10089337 | J38: ='Property-Level CF'!DI45 -> 2.2070377 | K38: ='Property-Level CF'!DI42 -> 0.081174707 | L38: ='Property-Level CF'!DI20 -> 0.0095445431 | N38: IRR | O38: ='Portfolio-Level CF'!M44 -> 0.10385787
B39: Total | C39: =SUM(C37:C38) -> 2284000 | E39: =E29 -> 40 Old Ridgebury Road, Danbury, CT 06810 | F39: ='Property-Level CF'!EH10 -> 1567320 | G39: =(F39/L9)*(1-'Portfolio-Level CF'!$AC$52) -> 30835681 | H39: =G39-J9 -> 3998899 | I39: ='Property-Level CF'!EH44 -> 0.093715507 | J39: ='Property-Level CF'!EH45 -> 2.1235596 | K39: ='Property-Level CF'!CJ42 -> 0.077349589 | L39: ='Property-Level CF'!EH20 -> 0.0089853664 | N39: Equity Multiple | O39: ='Portfolio-Level CF'!M45 -> 2.2381653 | R39: IRR | S39: ='Portfolio-Level CF'!M68 -> 0.14754039
E40: Total | F40: =SUM(F34:F39) -> 6512958 | G40: =F40/'Portfolio-Level CF'!M18*(1-'Portfolio-Level CF'!AC52) -> 1.2051134e+08 | H40: =G40-L30 -> 16760905 | I40: ='Portfolio-Level CF'!M44 -> 0.10385787 | J40: ='Portfolio-Level CF'!M45 -> 2.2381653 | K40: ='Portfolio-Level CF'!M42 -> 0.077659323 | L40: ='Portfolio-Level CF'!M20 -> 0.010811585 | N40: Avg Cash-on-Cash | O40: ='Portfolio-Level CF'!M42 -> 0.077659323 | R40: Equity Multiple | S40: ='Portfolio-Level CF'!M69 -> 2.2381653
...

Sheet Portfolio-Level CF
B2: CASH FLOW | O2: Year | P2: =D5 -> Year 1 | Q2: =E5 -> Year 2 | R2: =F5 -> Year 3 | S2: =G5 -> Year 4 | T2: =H5 -> Year 5 | U2: =I5 -> Year 6 | V2: =J5 -> Year 7 | W2: =K5 -> Year 8 | ... Y2: =M5 -> Year 10 | AA2: CASH FLOW
B3: Portfolio-Level Cash Flow Roll-Up | O3: Unlevered IRR | P3: =IRR(P4:P15) -> 0.0095634648 | Q3: =IRR(Q4:Q15) -> 0.036675356 | R3: =IRR(R4:R15) -> 0.060475501 | S3: =IRR(S4:S15) -> 0.061822143 | T3: =IRR(T4:T15) -> 0.0644085 | U3: =IRR(U4:U15) -> 0.063805188 | V3: =IRR(V4:V15) -> 0.065162092 | W3: =IRR(W4:W15) -> 0.066281943 | ... Y3: =IRR(Y4:Y15) -> 0.066186186 | AA3: Property-Level Cash Flow
G4: =(H10-'Rent Roll'!K12) -> 5779833.2 | H4: =G4/99100000 -> 0.058323241 | O4: 0 | P4: =C16 -> -1.0375044e+08 | Q4: =P4 -> -1.0375044e+08 | R4: =Q4 -> -1.0375044e+08 | S4: =R4 -> -1.0375044e+08 | T4: =S4 -> -1.0375044e+08 | U4: =T4 -> -1.0375044e+08 | V4: =U4 -> -1.0375044e+08 | W4: =V4 -> -1.0375044e+08 | X4: =W4 -> -1.0375044e+08 | Y4: =X4 -> -1.0375044e+08
C5: Year 0 | D5: Year 1 | E5: Year 2 | F5: Year 3 | G5: Year 4 | H5: Year 5 | I5: Year 6 | J5: Year 7 | K5: Year 8 | L5: Year 9 | M5: Year 10 | O5: =O4+1 -> 1 | P5: =D23+D14 -> 1.0474265e+08 | Q5: =D14 -> 4986605.5 | R5: =Q5 -> 4986605.5 | S5: =R5 -> 4986605.5 | T5: =S5 -> 4986605.5 | U5: =T5 -> 4986605.5 | V5: =U5 -> 4986605.5 | W5: =V5 -> 4986605.5 | X5: =W5 -> 4986605.5 | Y5: =X5 -> 4986605.5 | AC5: ='Portfolio-Level CF'!D5 -> Year 1 | AD5: ='Portfolio-Level CF'!E5 -> Year 2 | AE5: ='Portfolio-Level CF'!F5 -> Year 3 | AF5: ='Portfolio-Level CF'!G5 -> Year 4 | AG5: ='Portfolio-Level CF'!H5 -> Year 5 | AH5: ='Portfolio-Level CF'!I5 -> Year 6 | AI5: ='Portfolio-Level CF'!J5 -> Year 7 | AJ5: ='Portfolio-Level CF'!K5 -> Year 8 | ... AL5: ='Portfolio-Level CF'!M5 -> Year 10
B6: Year Ending | C6: 44377 | D6: 44742 | E6: 45107 | F6: 45473 | G6: 45838 | H6: 46203 | I6: 46568 | J6: 46934 | K6: 47299 | L6: 47664 | M6: 48029 | O6: =O5+1 -> 2 | Q6: =E23+E14 -> 1.0633067e+08 | R6: =E14 -> 5314553.5 | S6: =R6 -> 5314553.5 | T6: =S6 -> 5314553.5 | U6: =T6 -> 5314553.5 | V6: =U6 -> 5314553.5 | W6: =V6 -> 5314553.5 | X6: =W6 -> 5314553.5 | Y6: =X6 -> 5314553.5 | AA6: # | AB6: Year Ending | AC6: ='Portfolio-Level CF'!D6 -> 44742 | AD6: ='Portfolio-Level CF'!E6 -> 45107 | AE6: ='Portfolio-Level CF'!F6 -> 45473 | AF6: ='Portfolio-Level CF'!G6 -> 45838 | AG6: ='Portfolio-Level CF'!H6 -> 46203 | AH6: ='Portfolio-Level CF'!I6 -> 46568 | AI6: ='Portfolio-Level CF'!J6 -> 46934 | AJ6: ='Portfolio-Level CF'!K6 -> 47299 | ... AL6: ='Portfolio-Level CF'!M6 -> 48029
B7: Average Occupancy % | D7: ='Occupancy Report'!D24 -> 0.95533979 | E7: ='Occupancy Report'!H24 -> 1 | F7: ='Occupancy Report'!L24 -> 0.99949042 | G7: ='Occupancy Report'!P24 -> 0.99694165 | H7: ='Occupancy Report'!T24 -> 1 | I7: ='Occupancy Report'!X24 -> 0.99211685 | J7: ='Occupancy Report'!AB24 -> 0.99582284 | K7: ='Occupancy Report'!AF24 -> 0.99945537 | L7: ='Occupancy Report'!AJ24 -> 0.9959533 | M7: ='Occupancy Report'!AN24 -> 0.99590812 | O7: =O6+1 -> 3 | R7: =F23+F14 -> 1.1249087e+08 | S7: =F14 -> 5626184.5 | T7: =S7 -> 5626184.5 | U7: =T7 -> 5626184.5 | V7: =U7 -> 5626184.5 | W7: =V7 -> 5626184.5 | X7: =W7 -> 5626184.5 | Y7: =X7 -> 5626184.5 | AA7: - | AB7: Portfolio Wrap-up
O8: =O7+1 -> 4 | S8: =G23+G14 -> 1.139497e+08 | T8: =G14 -> 5459582.5 | U8: =T8 -> 5459582.5 | V8: =U8 -> 5459582.5 | W8: =V8 -> 5459582.5 | X8: =W8 -> 5459582.5 | Y8: =X8 -> 5459582.5 | AB8: EGR | AC8: =SUMIF($AB$14:$AB$145,$AB8,AC14:AC145) -> 7185904 | AD8: =SUMIF($AB$14:$AB$145,$AB8,AD14:AD145) -> 7620803 | AE8: =SUMIF($AB$14:$AB$145,$AB8,AE14:AE145) -> 8000831 | AF8: =SUMIF($AB$14:$AB$145,$AB8,AF14:AF145) -> 8140118 | AG8: =SUMIF($AB$14:$AB$145,$AB8,AG14:AG145) -> 8327368 | AH8: =SUMIF($AB$14:$AB$145,$AB8,AH14:AH145) -> 8415129 | AI8: =SUMIF($AB$14:$AB$145,$AB8,AI14:AI145) -> 8623077 | AJ8: =SUMIF($AB$14:$AB$145,$AB8,AJ14:AJ145) -> 8819545 | ... AL8: =SUMIF($AB$14:$AB$145,$AB8,AL14:AL145) -> 9141460
B9: Effective Gross Rent | D9: ='Portfolio-Level CF'!AC8 -> 7185904 | E9: ='Portfolio-Level CF'!AD8 -> 7620803 | F9: ='Portfolio-Level CF'!AE8 -> 8000831 | G9: ='Portfolio-Level CF'!AF8 -> 8140118 | H9: ='Portfolio-Level CF'!AG8 -> 8327368 | I9: ='Portfolio-Level CF'!AH8 -> 8415129 | J9: ='Portfolio-Level CF'!AI8 -> 8623077 | K9: ='Portfolio-Level CF'!AJ8 -> 8819545 | ... M9: ='Portfolio-Level CF'!AL8 -> 9141460 | O9: =O8+1 -> 5 | T9: =H23+H14 -> 1.1675741e+08 | U9: =H14 -> 5897375.5 | V9: =U9 -> 5897375.5 | W9: =V9 -> 5897375.5 | X9: =W9 -> 5897375.5 | Y9: =X9 -> 5897375.5 | AB9: NOI | AC9: =IF(AC$5="","",SUMIF($AB$14:$AB$145,$AB$9,AC14:AC145)) -> 5086317 | AD9: =IF(AD$5="","",SUMIF($AB$14:$AB$145,$AB$9,AD14:AD145)) -> 5459796 | AE9: =IF(AE$5="","",SUMIF($AB$14:$AB$145,$AB$9,AE14:AE145)) -> 5779539 | AF9: =IF(AF$5="","",SUMIF($AB$14:$AB$145,$AB$9,AF14:AF145)) -> 5865233 | AG9: =IF(AG$5="","",SUMIF($AB$14:$AB$145,$AB$9,AG14:AG145)) -> 5996067 | AH9: =IF(AH$5="","",SUMIF($AB$14:$AB$145,$AB$9,AH14:AH145)) -> 6029402 | AI9: =IF(AI$5="","",SUMIF($AB$14:$AB$145,$AB$9,AI14:AI145)) -> 6177842 | AJ9: =IF(AJ$5="","",SUMIF($AB$14:$AB$145,$AB$9,AJ14:AJ145)) -> 6313834 | ... AL9: =IF(AL$5="","",SUMIF($AB$14:$AB$145,$AB$9,AL14:AL145)) -> 6512958
B10: Net Operating Income | D10: ='Portfolio-Level CF'!AC9 -> 5086317 | E10: ='Portfolio-Level CF'!AD9 -> 5459796 | F10: ='Portfolio-Level CF'!AE9 -> 5779539 | G10: ='Portfolio-Level CF'!AF9 -> 5865233 | H10: ='Portfolio-Level CF'!AG9 -> 5996067 | I10: ='Portfolio-Level CF'!AH9 -> 6029402 | J10: ='Portfolio-Level CF'!AI9 -> 6177842 | K10: ='Portfolio-Level CF'!AJ9 -> 6313834 | ... M10: ='Portfolio-Level CF'!AL9 -> 6512958 | O10: =O9+1 -> 6 | U10: =I23+I14 -> 1.175448e+08 | V10: =I14 -> 5930710.5 | W10: =V10 -> 5930710.5 | X10: =W10 -> 5930710.5 | Y10: =X10 -> 5930710.5 | AB10: NCF before DS | AC10: =SUMIF($AB$14:$AB$145,$AB$10,AC14:AC145) -> 4986605.5 | AD10: =SUMIF($AB$14:$AB$145,$AB$10,AD14:AD145) -> 5314553.5 | AE10: =SUMIF($AB$14:$AB$145,$AB$10,AE14:AE145) -> 5626184.5 | AF10: =SUMIF($AB$14:$AB$145,$AB$10,AF14:AF145) -> 5459582.5 | AG10: =SUMIF($AB$14:$AB$145,$AB$10,AG14:AG145) -> 5897375.5 | AH10: =SUMIF($AB$14:$AB$145,$AB$10,AH14:AH145) -> 5930710.5 | AI10: =SUMIF($AB$14:$AB$145,$AB$10,AI14:AI145) -> 5631357.5 | AJ10: =SUMIF($AB$14:$AB$145,$AB$10,AJ14:AJ145) -> 6215142.5 | ... AL10: =SUMIF($AB$14:$AB$145,$AB$10,AL14:AL145) -> 5967977.5
B11: Tenant Improvement | D11: ='Property-Level CF'!CA11+'Property-Level CF'!DY11+'Property-Level CF'!CZ11+'Property-Level CF'!D11+'Property-Level CF'!AC11+'Property-Level CF'!BB11 -> 0 | E11: ='Property-Level CF'!CB11+'Property-Level CF'!DZ11+'Property-Level CF'!DA11+'Property-Level CF'!E11+'Property-Level CF'!AD11+'Property-Level CF'!BC11 -> 41850 | F11: ='Property-Level CF'!CC11+'Property-Level CF'!EA11+'Property-Level CF'!DB11+'Property-Level CF'!F11+'Property-Level CF'!AE11+'Property-Level CF'!BD11 -> 45149 | G11: ='Property-Level CF'!CD11+'Property-Level CF'!EB11+'Property-Level CF'!DC11+'Property-Level CF'!G11+'Property-Level CF'!AF11+'Property-Level CF'!BE11 -> 253532 | H11: ='Property-Level CF'!CE11+'Property-Level CF'!EC11+'Property-Level CF'!DD11+'Property-Level CF'!H11+'Property-Level CF'!AG11+'Property-Level CF'!BF11 -> 0 | I11: ='Property-Level CF'!CF11+'Property-Level CF'!ED11+'Property-Level CF'!DE11+'Property-Level CF'!I11+'Property-Level CF'!AH11+'Property-Level CF'!BG11 -> 0 | J11: ='Property-Level CF'!CG11+'Property-Level CF'!EE11+'Property-Level CF'!DF11+'Property-Level CF'!J11+'Property-Level CF'!AI11+'Property-Level CF'!BH11 -> 427040 | K11: ='Property-Level CF'!CH11+'Property-Level CF'!EF11+'Property-Level CF'!DG11+'Property-Level CF'!K11+'Property-Level CF'!AJ11+'Property-Level CF'!BI11 -> 0 | ... M11: ='Property-Level CF'!CJ11+'Property-Level CF'!EH11+'Property-Level CF'!DI11+'Property-Level CF'!M11+'Property-Level CF'!AL11+'Property-Level CF'!BK11 -> 403214 | O11: =O10+1 -> 7 | V11: =J23+J14 -> 1.199805e+08 | W11: =J14 -> 5631357.5 | X11: =W11 -> 5631357.5 | Y11: =X11 -> 5631357.5 | AB11: DS | AC11: =SUMIF($AB$14:$AB$145,$AB$10,AC15:AC146) -> 2772962.6 | AD11: =SUMIF($AB$14:$AB$145,$AB$10,AD15:AD146) -> 2772962.6 | AE11: =SUMIF($AB$14:$AB$145,$AB$10,AE15:AE146) -> 2772962.6 | AF11: =SUMIF($AB$14:$AB$145,$AB$10,AF15:AF146) -> 2772962.6 | AG11: =SUMIF($AB$14:$AB$145,$AB$10,AG15:AG146) -> 2772962.6 | AH11: =SUMIF($AB$14:$AB$145,$AB$10,AH15:AH146) -> 2772962.6 | AI11: =SUMIF($AB$14:$AB$145,$AB$10,AI15:AI146) -> 2772962.6 | AJ11: =SUMIF($AB$14:$AB$145,$AB$10,AJ15:AJ146) -> 2772962.6 | ... AL11: =SUMIF($AB$14:$AB$145,$AB$10,AL15:AL146) -> 2772962.6
B12: Leasing Commissions | D12: ='Property-Level CF'!CA12+'Property-Level CF'!DY12+'Property-Level CF'!CZ12+'Property-Level CF'!D12+'Property-Level CF'!AC12+'Property-Level CF'!BB12 -> 1020 | E12: ='Property-Level CF'!CB12+'Property-Level CF'!DZ12+'Property-Level CF'!DA12+'Property-Level CF'!E12+'Property-Level CF'!AD12+'Property-Level CF'!BC12 -> 4701 | F12: ='Property-Level CF'!CC12+'Property-Level CF'!EA12+'Property-Level CF'!DB12+'Property-Level CF'!F12+'Property-Level CF'!AE12+'Property-Level CF'!BD12 -> 9514 | G12: ='Property-Level CF'!CD12+'Property-Level CF'!EB12+'Property-Level CF'!DC12+'Property-Level CF'!G12+'Property-Level CF'!AF12+'Property-Level CF'!BE12 -> 53427 | H12: ='Property-Level CF'!CE12+'Property-Level CF'!EC12+'Property-Level CF'!DD12+'Property-Level CF'!H12+'Property-Level CF'!AG12+'Property-Level CF'!BF12 -> 0 | I12: ='Property-Level CF'!CF12+'Property-Level CF'!ED12+'Property-Level CF'!DE12+'Property-Level CF'!I12+'Property-Level CF'!AH12+'Property-Level CF'!BG12 -> 0 | J12: ='Property-Level CF'!CG12+'Property-Level CF'!EE12+'Property-Level CF'!DF12+'Property-Level CF'!J12+'Property-Level CF'!AI12+'Property-Level CF'!BH12 -> 20753 | K12: ='Property-Level CF'!CH12+'Property-Level CF'!EF12+'Property-Level CF'!DG12+'Property-Level CF'!K12+'Property-Level CF'!AJ12+'Property-Level CF'!BI12 -> 0 | ... M12: ='Property-Level CF'!CJ12+'Property-Level CF'!EH12+'Property-Level CF'!DI12+'Property-Level CF'!M12+'Property-Level CF'!AL12+'Property-Level CF'!BK12 -> 43075 | O12: =O11+1 -> 8 | W12: =K23+K14 -> 1.2303209e+08 | X12: =K14 -> 6215142.5 | Y12: =X12 -> 6215142.5 | AB12: NCF after DS | AC12: =AC10-AC11 -> 2213642.9 | AD12: =AD10-AD11 -> 2541590.9 | AE12: =AE10-AE11 -> 2853221.9 | AF12: =AF10-AF11 -> 2686619.9 | AG12: =AG10-AG11 -> 3124412.9 | AH12: =AH10-AH11 -> 3157747.9 | AI12: =AI10-AI11 -> 2858394.9 | AJ12: =AJ10-AJ11 -> 3442179.9 | ... AL12: =AL10-AL11 -> 3195014.9
B13: Capital Reserves | D13: =Summary!C12*Summary!$C$11 -> 98691.5 | E13: =D13 -> 98691.5 | F13: =E13 -> 98691.5 | G13: =F13 -> 98691.5 | H13: =G13 -> 98691.5 | I13: =H13 -> 98691.5 | J13: =I13 -> 98691.5 | K13: =J13 -> 98691.5 | L13: =K13 -> 98691.5 | M13: =L13 -> 98691.5 | O13: =O12+1 -> 9 | X13: =L23+L14 -> 1.2400989e+08 | Y13: =L14 -> 5808113.5
B14: Net Cash Flow Before Debt Service | D14: =D10-SUM(D11:D13) -> 4986605.5 | E14: =E10-SUM(E11:E13) -> 5314553.5 | F14: =F10-SUM(F11:F13) -> 5626184.5 | G14: =G10-SUM(G11:G13) -> 5459582.5 | H14: =H10-SUM(H11:H13) -> 5897375.5 | I14: =I10-SUM(I11:I13) -> 5930710.5 | J14: =J10-SUM(J11:J13) -> 5631357.5 | K14: =K10-SUM(K11:K13) -> 6215142.5 | ... M14: =M10-SUM(M11:M13) -> 5967977.5 | O14: =O13+1 -> 10 | Y14: =M15+M14 -> 1.2647932e+08 | AA14: 1 | AB14: 131 Kent
B15: Sale (Unlevered) | M15: =M23 -> 1.2051134e+08 | O15: =O14+1 -> 11 | AA15: =AB14&AB15 -> 131 KentEGR | AB15: =IF(AB14="","","EGR") -> EGR | AC15: ='Property-Level CF'!D9 -> 1080474 | AD15: ='Property-Level CF'!E9 -> 1104382 | AE15: ='Property-Level CF'!F9 -> 1120725 | AF15: ='Property-Level CF'!G9 -> 1124325 | AG15: ='Property-Level CF'!H9 -> 1174564 | AH15: ='Property-Level CF'!I9 -> 1131939 | AI15: ='Property-Level CF'!J9 -> 1155752 | AJ15: ='Property-Level CF'!K9 -> 1206302 | ... AL15: ='Property-Level CF'!M9 -> 1261766
B16: Unlevered Cash Flow | C16: =-Summary!J20 -> -1.0375044e+08 | D16: =D14+D15 -> 4986605.5 | E16: =E14+E15 -> 5314553.5 | F16: =F14+F15 -> 5626184.5 | G16: =G14+G15 -> 5459582.5 | H16: =H14+H15 -> 5897375.5 | I16: =I14+I15 -> 5930710.5 | J16: =J14+J15 -> 5631357.5 | K16: =K14+K15 -> 6215142.5 | ... M16: =M14+M15 -> 1.2647932e+08 | O16: Year | P16: =P2 -> Year 1 | Q16: =Q2 -> Year 2 | R16: =R2 -> Year 3 | S16: =S2 -> Year 4 | T16: =T2 -> Year 5 | U16: =U2 -> Year 6 | V16: =V2 -> Year 7 | W16: =W2 -> Year 8 | ... Y16: =Y2 -> Year 10 | AA16: =AB14&AB16 -> 131 KentNOI | AB16: =IF(AB14="","","NOI") -> NOI | AC16: ='Property-Level CF'!D10 -> 776823 | AD16: ='Property-Level CF'!E10 -> 792690 | AE16: ='Property-Level CF'!F10 -> 801674 | AF16: ='Property-Level CF'!G10 -> 798070 | AG16: ='Property-Level CF'!H10 -> 839376 | AH16: ='Property-Level CF'!I10 -> 790672 | AI16: ='Property-Level CF'!J10 -> 806147 | AJ16: ='Property-Level CF'!K10 -> 847300 | ... AL16: ='Property-Level CF'!M10 -> 884835
O17: Levered IRR | P17: =IRR(P18:P29) -> -0.051539351 | Q17: =IRR(Q18:Q29) -> 0.025747677 | R17: =IRR(R18:R29) -> 0.092909389 | S17: =IRR(S18:S29) -> 0.096104457 | T17: =IRR(T18:T29) -> 0.10227762 | U17: =IRR(U18:U29) -> 0.10024719 | V17: =IRR(V18:V29) -> 0.10306125 | W17: =IRR(W18:W29) -> 0.1051344 | ... Y17: =IRR(Y18:Y29) -> 0.10385787 | AA17: =AB14&AB17 -> 131 KentNCF before DS | AB17: NCF before DS | AC17: ='Property-Level CF'!D14 -> 761132.5 | AD17: ='Property-Level CF'!E14 -> 731468.5 | AE17: ='Property-Level CF'!F14 -> 732340.5 | AF17: ='Property-Level CF'!G14 -> 476440.5 | AG17: ='Property-Level CF'!H14 -> 824705.5 | AH17: ='Property-Level CF'!I14 -> 776001.5 | AI17: ='Property-Level CF'!J14 -> 343683.5 | AJ17: ='Property-Level CF'!K14 -> 832629.5 | ... AL17: ='Property-Level CF'!M14 -> 638163.5
B18: Cap Rate at Sale | D18: =Summary!L20 -> 0.049024535 | E18: =E10/(E23/(1-'Portfolio-Level CF'!$AC$52)) -> 0.051967885 | F18: =F10/(F23/(1-'Portfolio-Level CF'!$AC$52)) -> 0.052000592 | G18: =G10/(G23/(1-'Portfolio-Level CF'!$AC$52)) -> 0.051980968 | H18: =H10/(H23/(1-'Portfolio-Level CF'!$AC$52)) -> 0.052004482 | I18: =I10/(I23/(1-'Portfolio-Level CF'!$AC$52)) -> 0.051940308 | J18: =J10/(J23/(1-'Portfolio-Level CF'!$AC$52)) -> 0.051946125 | K18: =K10/(K23/(1-'Portfolio-Level CF'!$AC$52)) -> 0.051968073 | L18: =L10/(L23/(1-'Portfolio-Level CF'!$AC$52)) -> 0.051943476 | M18: =M10/(M23/(1-'Portfolio-Level CF'!$AC$52)) -> 0.051963649 | O18: 0 | P18: =P4+Summary!I30 -> -36312653 | Q18: =P18 -> -36312653 | R18: =Q18 -> -36312653 | S18: =R18 -> -36312653 | T18: =S18 -> -36312653 | U18: =T18 -> -36312653 | V18: =U18 -> -36312653 | W18: =V18 -> -36312653 | X18: =W18 -> -36312653 | Y18: =X18 -> -36312653 | AB18: DS | AC18: ='Property-Level CF'!D30 -> 358737.83 | AD18: ='Property-Level CF'!E30 -> 358737.83 | AE18: ='Property-Level CF'!F30 -> 358737.83 | AF18: ='Property-Level CF'!G30 -> 358737.83 | AG18: ='Property-Level CF'!H30 -> 358737.83 | AH18: ='Property-Level CF'!I30 -> 358737.83 | AI18: ='Property-Level CF'!J30 -> 358737.83 | AJ18: ='Property-Level CF'!K30 -> 358737.83 | ... AL18: ='Property-Level CF'!M30 -> 358737.83
B19: Implied Exit Cap Rate | D19: =(D10/$D$23)*(1-'Portfolio-Level CF'!$AC$52) -> 0.049024535 | E19: =(E10/$D$23)*(1-'Portfolio-Level CF'!$AC$52) -> 0.052624318 | F19: =(F10/$D$23)*(1-'Portfolio-Level CF'!$AC$52) -> 0.055706165 | G19: =(G10/$D$23)*(1-'Portfolio-Level CF'!$AC$52) -> 0.056532128 | H19: =(H10/$D$23)*(1-'Portfolio-Level CF'!$AC$52) -> 0.057793173 | I19: =(I10/$D$23)*(1-'Portfolio-Level CF'!$AC$52) -> 0.058114473 | J19: =(J10/$D$23)*(1-'Portfolio-Level CF'!$AC$52) -> 0.059545214 | K19: =(K10/$D$23)*(1-'Portfolio-Level CF'!$AC$52) -> 0.060855975 | ... M19: =(M10/$D$23)*(1-'Portfolio-Level CF'!$AC$52) -> 0.062775234 | O19: =O18+1 -> 1 | P19: =D33+D39 -> 34441123 | Q19: =D39 -> 2122861.3 | R19: =Q19 -> 2122861.3 | S19: =R19 -> 2122861.3 | T19: =S19 -> 2122861.3 | U19: =T19 -> 2122861.3 | V19: =U19 -> 2122861.3 | W19: =V19 -> 2122861.3 | X19: =W19 -> 2122861.3 | Y19: =X19 -> 2122861.3 | AB19: NCF after DS | AC19: =AC17-AC18 -> 402394.67 | AD19: =AD17-AD18 -> 372730.67 | AE19: =AE17-AE18 -> 373602.67 | AF19: =AF17-AF18 -> 117702.67 | AG19: =AG17-AG18 -> 465967.67 | AH19: =AH17-AH18 -> 417263.67 | AI19: =AI17-AI18 -> -15054.326 | AJ19: =AJ17-AJ18 -> 473891.67 | ... AL19: =AL17-AL18 -> 279425.67
B20: Accretive (Dilutive) Cap Spread | D20: =D19-D18 -> 0 | E20: =E19-E18 -> 0.00065643245 | F20: =F19-F18 -> 0.0037055733 | G20: =G19-G18 -> 0.0045511601 | H20: =H19-H18 -> 0.0057886916 | I20: =I19-I18 -> 0.0061741648 | J20: =J19-J18 -> 0.0075990892 | K20: =K19-K18 -> 0.0088879018 | ... M20: =M19-M18 -> 0.010811585 | O20: =O19+1 -> 2 | Q20: =E33+E39 -> 36029139 | R20: =E39 -> 2450809.3 | S20: =R20 -> 2450809.3 | T20: =S20 -> 2450809.3 | U20: =T20 -> 2450809.3 | V20: =U20 -> 2450809.3 | W20: =V20 -> 2450809.3 | X20: =W20 -> 2450809.3 | Y20: =X20 -> 2450809.3 | AA20: 2 | AB20: 164 Mount Pleasant
B21: REIT GAAP Accounting Cap Rate Average | D21: =AVERAGE($D$19:D19) -> 0.049024535 | E21: =AVERAGE($D$19:E19) -> 0.050824427 | F21: =AVERAGE($D$19:F19) -> 0.052451673 | G21: =AVERAGE($D$19:G19) -> 0.053471787 | H21: =AVERAGE($D$19:H19) -> 0.054336064 | I21: =AVERAGE($D$19:I19) -> 0.054965799 | J21: =AVERAGE($D$19:J19) -> 0.055620001 | K21: =AVERAGE($D$19:K19) -> 0.056274498 | ... M21: =AVERAGE($D$19:M19) -> 0.057451948 | O21: =O20+1 -> 3 | R21: =F33+F39 -> 42189339 | S21: =F39 -> 2762440.3 | T21: =S21 -> 2762440.3 | U21: =T21 -> 2762440.3 | V21: =U21 -> 2762440.3 | W21: =V21 -> 2762440.3 | X21: =W21 -> 2762440.3 | Y21: =X21 -> 2762440.3 | AA21: =AB20&AB21 -> 164 Mount Pleasant EGR | AB21: EGR | AC21: ='Property-Level CF'!AC9 -> 753930 | AD21: ='Property-Level CF'!AD9 -> 906249 | AE21: ='Property-Level CF'!AE9 -> 1085628 | AF21: ='Property-Level CF'!AF9 -> 1112856 | AG21: ='Property-Level CF'!AG9 -> 1139458 | AH21: ='Property-Level CF'!AH9 -> 1156756 | AI21: ='Property-Level CF'!AI9 -> 1174243 | AJ21: ='Property-Level CF'!AJ9 -> 1192002 | ... AL21: ='Property-Level CF'!AL9 -> 1215445
O22: =O21+1 -> 4 | S22: =G33+G39 -> 43648176 | T22: =G39 -> 2595838.3 | U22: =T22 -> 2595838.3 | V22: =U22 -> 2595838.3 | W22: =V22 -> 2595838.3 | X22: =W22 -> 2595838.3 | Y22: =X22 -> 2595838.3 | AA22: =AB20&AB22 -> 164 Mount Pleasant NOI | AB22: NOI | AC22: ='Property-Level CF'!AC10 -> 421291 | AD22: ='Property-Level CF'!AD10 -> 560979 | AE22: ='Property-Level CF'!AE10 -> 726550 | AF22: ='Property-Level CF'!AF10 -> 744800 | AG22: ='Property-Level CF'!AG10 -> 762241 | AH22: ='Property-Level CF'!AH10 -> 770468 | AI22: ='Property-Level CF'!AI10 -> 778664 | AJ22: ='Property-Level CF'!AJ10 -> 786906 | ... AL22: ='Property-Level CF'!AL10 -> 791022
B23: Net Sale Price | D23: ='Property-Level CF'!CA23+'Property-Level CF'!DY23+'Property-Level CF'!CZ23+'Property-Level CF'!D23+'Property-Level CF'!AC23+'Property-Level CF'!BB23 -> 99756046 | E23: ='Property-Level CF'!CB23+'Property-Level CF'!DZ23+'Property-Level CF'!DA23+'Property-Level CF'!E23+'Property-Level CF'!AD23+'Property-Level CF'!BC23 -> 1.0101611e+08 | F23: ='Property-Level CF'!CC23+'Property-Level CF'!EA23+'Property-Level CF'!DB23+'Property-Level CF'!F23+'Property-Level CF'!AE23+'Property-Level CF'!BD23 -> 1.0686468e+08 | G23: ='Property-Level CF'!CD23+'Property-Level CF'!EB23+'Property-Level CF'!DC23+'Property-Level CF'!G23+'Property-Level CF'!AF23+'Property-Level CF'!BE23 -> 1.0849012e+08 | H23: ='Property-Level CF'!CE23+'Property-Level CF'!EC23+'Property-Level CF'!DD23+'Property-Level CF'!H23+'Property-Level CF'!AG23+'Property-Level CF'!BF23 -> 1.1086003e+08 | I23: ='Property-Level CF'!CF23+'Property-Level CF'!ED23+'Property-Level CF'!DE23+'Property-Level CF'!I23+'Property-Level CF'!AH23+'Property-Level CF'!BG23 -> 1.1161409e+08 | J23: ='Property-Level CF'!CG23+'Property-Level CF'!EE23+'Property-Level CF'!DF23+'Property-Level CF'!J23+'Property-Level CF'!AI23+'Property-Level CF'!BH23 -> 1.1434915e+08 | K23: ='Property-Level CF'!CH23+'Property-Level CF'!EF23+'Property-Level CF'!DG23+'Property-Level CF'!K23+'Property-Level CF'!AJ23+'Property-Level CF'!BI23 -> 1.1681694e+08 | ... M23: ='Property-Level CF'!CJ23+'Property-Level CF'!EH23+'Property-Level CF'!DI23+'Property-Level CF'!M23+'Property-Level CF'!AL23+'Property-Level CF'!BK23 -> 1.2051134e+08 | O23: =O22+1 -> 5 | T23: =H33+H39 -> 46455877 | U23: =H39 -> 3033631.3 | V23: =U23 -> 3033631.3 | W23: =V23 -> 3033631.3 | X23: =W23 -> 3033631.3 | Y23: =X23 -> 3033631.3 | AA23: =AB20&AB23 -> 164 Mount Pleasant NCF before DS | AB23: NCF before DS | AC23: ='Property-Level CF'!AC14 -> 408299 | AD23: ='Property-Level CF'!AD14 -> 547987 | AE23: ='Property-Level CF'!AE14 -> 713558 | AF23: ='Property-Level CF'!AF14 -> 731808 | AG23: ='Property-Level CF'!AG14 -> 749249 | AH23: ='Property-Level CF'!AH14 -> 757476 | AI23: ='Property-Level CF'!AI14 -> 765672 | AJ23: ='Property-Level CF'!AJ14 -> 773914 | ... AL23: ='Property-Level CF'!AL14 -> 563742
B24: Net Sale Price PSF | D24: =D23/Summary!$C$12 -> 505.3933 | E24: =E23/Summary!$C$12 -> 511.77718 | F24: =F23/Summary!$C$12 -> 541.40773 | G24: =G23/Summary!$C$12 -> 549.64268 | H24: =H23/Summary!$C$12 -> 561.64933 | I24: =I23/Summary!$C$12 -> 565.4696 | J24: =J23/Summary!$C$12 -> 579.32622 | K24: =K23/Summary!$C$12 -> 591.82879 | ... M24: =M23/Summary!$C$12 -> 610.5457 | O24: =O23+1 -> 6 | U24: =I33+I39 -> 47243268 | V24: =I39 -> 3066966.3 | W24: =V24 -> 3066966.3 | X24: =W24 -> 3066966.3 | Y24: =X24 -> 3066966.3 | AB24: DS | AC24: ='Property-Level CF'!AC30 -> 292979.76 | AD24: ='Property-Level CF'!AD30 -> 292979.76 | AE24: ='Property-Level CF'!AE30 -> 292979.76 | AF24: ='Property-Level CF'!AF30 -> 292979.76 | AG24: ='Property-Level CF'!AG30 -> 292979.76 | AH24: ='Property-Level CF'!AH30 -> 292979.76 | AI24: ='Property-Level CF'!AI30 -> 292979.76 | AJ24: ='Property-Level CF'!AJ30 -> 292979.76 | ... AL24: ='Property-Level CF'!AL30 -> 292979.76
O25: =O24+1 -> 7 | V25: =J33+J39 -> 49678976 | W25: =J39 -> 2767613.3 | X25: =W25 -> 2767613.3 | Y25: =X25 -> 2767613.3 | AB25: NCF after DS | AC25: =AC23-AC24 -> 115319.24 | AD25: =AD23-AD24 -> 255007.24 | AE25: =AE23-AE24 -> 420578.24 | AF25: =AF23-AF24 -> 438828.24 | AG25: =AG23-AG24 -> 456269.24 | AH25: =AH23-AH24 -> 464496.24 | AI25: =AI23-AI24 -> 472692.24 | AJ25: =AJ23-AJ24 -> 480934.24 | ... AL25: =AL23-AL24 -> 270762.24
B26: Unlevered IRR | D26: =P3 -> 0.0095634648 | E26: =Q3 -> 0.036675356 | F26: =R3 -> 0.060475501 | G26: =S3 -> 0.061822143 | H26: =T3 -> 0.0644085 | I26: =U3 -> 0.063805188 | J26: =V3 -> 0.065162092 | K26: =W3 -> 0.066281943 | ... M26: =Y3 -> 0.066186186 | O26: =O25+1 -> 8 | W26: =K33+K39 -> 52730557 | X26: =K39 -> 3351398.3 | Y26: =X26 -> 3351398.3 | AA26: 3 | AB26: 170 Mount Pleasant
B27: Unlevered Equity Multiple | D27: =(SUM($D$14:D14)+D23)/-P4 -> 1.0095635 | E27: =(SUM($D$14:E14)+E23)/-Q4 -> 1.0729331 | F27: =(SUM($D$14:F14)+F23)/-R4 -> 1.1835326 | G27: =(SUM($D$14:G14)+G23)/-S4 -> 1.2518217 | H27: =(SUM($D$14:H14)+H23)/-T4 -> 1.331506 | I27: =(SUM($D$14:I14)+I23)/-U4 -> 1.3959372 | J27: =(SUM($D$14:J14)+J23)/-V4 -> 1.4765771 | K27: =(SUM($D$14:K14)+K23)/-W4 -> 1.5602677 | ... M27: =(SUM($D$14:M14)+M23)/-Y4 -> 1.7093802 | O27: =O26+1 -> 9 | X27: =L33+L39 -> 53708361 | Y27: =L39 -> 2944369.3 | AA27: =AB26&AB27 -> 170 Mount Pleasant EGR | AB27: EGR | AC27: ='Property-Level CF'!BB9 -> 955031 | AD27: ='Property-Level CF'!BC9 -> 1124079 | AE27: ='Property-Level CF'!BD9 -> 1217274 | AF27: ='Property-Level CF'!BE9 -> 1232295 | AG27: ='Property-Level CF'!BF9 -> 1247438 | AH27: ='Property-Level CF'!BG9 -> 1263167 | AI27: ='Property-Level CF'!BH9 -> 1330801 | AJ27: ='Property-Level CF'!BI9 -> 1357587 | ... AL27: ='Property-Level CF'!BK9 -> 1389233
O28: =O27+1 -> 10 | Y28: =M33+M36+M38 -> 56177792 | AA28: =AB26&AB28 -> 170 Mount Pleasant NOI | AB28: NOI | AC28: ='Property-Level CF'!BB10 -> 638299 | AD28: ='Property-Level CF'!BC10 -> 794615 | AE28: ='Property-Level CF'!BD10 -> 877384 | AF28: ='Property-Level CF'!BE10 -> 884405 | AG28: ='Property-Level CF'!BF10 -> 891356 | AH28: ='Property-Level CF'!BG10 -> 898681 | AI28: ='Property-Level CF'!BH10 -> 956057 | AJ28: ='Property-Level CF'!BI10 -> 973687 | ... AL28: ='Property-Level CF'!BK10 -> 987095
B29: Loan Balance | D29: =Summary!$C$17 -> 67437784 | E29: =D29 -> 67437784 | F29: =E29 -> 67437784 | G29: =F29 -> 67437784 | H29: =G29 -> 67437784 | I29: =H29 -> 67437784 | J29: =I29 -> 67437784 | K29: =J29 -> 67437784 | L29: =K29 -> 67437784 | M29: =L29 -> 67437784 | O29: =O28+1 -> 11 | AA29: =AB26&AB29 -> 170 Mount Pleasant NCF before DS | AB29: NCF before DS | AC29: ='Property-Level CF'!BB14 -> 623299 | AD29: ='Property-Level CF'!BC14 -> 779615 | AE29: ='Property-Level CF'!BD14 -> 862384 | AF29: ='Property-Level CF'!BE14 -> 869405 | AG29: ='Property-Level CF'!BF14 -> 876356 | AH29: ='Property-Level CF'!BG14 -> 883681 | AI29: ='Property-Level CF'!BH14 -> 941057 | AJ29: ='Property-Level CF'!BI14 -> 958687 | ... AL29: ='Property-Level CF'!BK14 -> 972095
B30: Debt Service | D30: ='Portfolio-Level CF'!AC11 -> 2772962.6 | E30: ='Portfolio-Level CF'!AD11 -> 2772962.6 | F30: ='Portfolio-Level CF'!AE11 -> 2772962.6 | G30: ='Portfolio-Level CF'!AF11 -> 2772962.6 | H30: ='Portfolio-Level CF'!AG11 -> 2772962.6 | I30: ='Portfolio-Level CF'!AH11 -> 2772962.6 | J30: ='Portfolio-Level CF'!AI11 -> 2772962.6 | K30: ='Portfolio-Level CF'!AJ11 -> 2772962.6 | ... M30: ='Portfolio-Level CF'!AL11 -> 2772962.6 | AB30: DS | AC30: ='Property-Level CF'!BB30 -> 376017.62 | AD30: ='Property-Level CF'!BC30 -> 376017.62 | AE30: ='Property-Level CF'!BD30 -> 376017.62 | AF30: ='Property-Level CF'!BE30 -> 376017.62 | AG30: ='Property-Level CF'!BF30 -> 376017.62 | AH30: ='Property-Level CF'!BG30 -> 376017.62 | AI30: ='Property-Level CF'!BH30 -> 376017.62 | AJ30: ='Property-Level CF'!BI30 -> 376017.62 | ... AL30: ='Property-Level CF'!BK30 -> 376017.62
B31: Debt Coverage Ratio | D31: =D10/D30 -> 1.8342537 | E31: =E10/E30 -> 1.9689396 | F31: =F10/F30 -> 2.084247 | G31: =G10/G30 -> 2.1151504 | H31: =H10/H30 -> 2.1623324 | I31: =I10/I30 -> 2.1743539 | J31: =J10/J30 -> 2.2278851 | K31: =K10/K30 -> 2.2769272 | ... M31: =M10/M30 -> 2.3487363 | O31: Portfolio Sale Price by Cap Rate by Exit Year | AB31: NCF after DS | AC31: =AC29-AC30 -> 247281.38 | AD31: =AD29-AD30 -> 403597.38 | AE31: =AE29-AE30 -> 486366.38 | AF31: =AF29-AF30 -> 493387.38 | AG31: =AG29-AG30 -> 500338.38 | AH31: =AH29-AH30 -> 507663.38 | AI31: =AI29-AI30 -> 565039.38 | AJ31: =AJ29-AJ30 -> 582669.38 | ... AL31: =AL29-AL30 -> 596077.38
O32: Cap Rate | P32: =P16 -> Year 1 | Q32: =Q16 -> Year 2 | R32: =R16 -> Year 3 | S32: =S16 -> Year 4 | T32: =T16 -> Year 5 | U32: =U16 -> Year 6 | V32: =V16 -> Year 7 | W32: =W16 -> Year 8 | ... Y32: =Y16 -> Year 10 | AA32: 4 | AB32: 2 Riverview
B33: Net Cash on Sale | D33: =D23-D29 -> 32318261 | E33: =E23-E29 -> 33578330 | F33: =F23-F29 -> 39426898 | G33: =G23-G29 -> 41052337 | H33: =H23-H29 -> 43422246 | I33: =I23-I29 -> 44176302 | J33: =J23-J29 -> 46911363 | K33: =K23-K29 -> 49379158 | L33: =L23-L29 -> 50763991 | M33: =M15-M29 -> 53073558 | O33: 0.05 | P33: =('Portfolio-Level CF'!D10/$O33)*(1-'Portfolio-Level CF'!$AC$52) -> 97809876 | Q33: =('Portfolio-Level CF'!E10/$O33)*(1-'Portfolio-Level CF'!$AC$52) -> 1.0499188e+08 | R33: =('Portfolio-Level CF'!F10/$O33)*(1-'Portfolio-Level CF'!$AC$52) -> 1.1114053e+08 | S33: =('Portfolio-Level CF'!G10/$O33)*(1-'Portfolio-Level CF'!$AC$52) -> 1.1278843e+08 | T33: =('Portfolio-Level CF'!H10/$O33)*(1-'Portfolio-Level CF'!$AC$52) -> 1.1530437e+08 | U33: =('Portfolio-Level CF'!I10/$O33)*(1-'Portfolio-Level CF'!$AC$52) -> 1.159454e+08 | V33: =('Portfolio-Level CF'!J10/$O33)*(1-'Portfolio-Level CF'!$AC$52) -> 1.187999e+08 | W33: =('Portfolio-Level CF'!K10/$O33)*(1-'Portfolio-Level CF'!$AC$52) -> 1.2141503e+08 | ... Y33: =('Portfolio-Level CF'!M10/$O33)*(1-'Portfolio-Level CF'!$AC$52) -> 1.2524418e+08 | AA33: =AB32&AB33 -> 2 Riverview EGR | AB33: EGR | AC33: ='Property-Level CF'!CA9 -> 1885346 | AD33: ='Property-Level CF'!CB9 -> 1921877 | AE33: ='Property-Level CF'!CC9 -> 1959053 | AF33: ='Property-Level CF'!CD9 -> 1997206 | AG33: ='Property-Level CF'!CE9 -> 2036006 | AH33: ='Property-Level CF'!CF9 -> 2075650 | AI33: ='Property-Level CF'!CG9 -> 2115923 | AJ33: ='Property-Level CF'!CH9 -> 2156964 | ... AL33: ='Property-Level CF'!CJ9 -> 2244371
B34: Net Gain | D34: =D33+$C$39 -> -3994391.8 | E34: =E33+$C$39 -> -2734323.1 | F34: =F33+$C$39 -> 3114245.3 | G34: =G33+$C$39 -> 4739684.4 | H34: =H33+$C$39 -> 7109593.1 | I34: =I33+$C$39 -> 7863648.5 | J34: =J33+$C$39 -> 10598710 | K34: =K33+$C$39 -> 13066505 | ... M34: =M33+$C$39 -> 16760905 | O34: =Summary!L10 -> 0.051247526 | P34: =('Portfolio-Level CF'!D10/$O34)*(1-'Portfolio-Level CF'!$AC$52) -> 95428875 | Q34: =('Portfolio-Level CF'!E10/$O34)*(1-'Portfolio-Level CF'!$AC$52) -> 1.0243604e+08 | R34: =('Portfolio-Level CF'!F10/$O34)*(1-'Portfolio-Level CF'!$AC$52) -> 1.0843502e+08 | S34: =('Portfolio-Level CF'!G10/$O34)*(1-'Portfolio-Level CF'!$AC$52) -> 1.100428e+08 | T34: =('Portfolio-Level CF'!H10/$O34)*(1-'Portfolio-Level CF'!$AC$52) -> 1.124975e+08 | U34: =('Portfolio-Level CF'!I10/$O34)*(1-'Portfolio-Level CF'!$AC$52) -> 1.1312292e+08 | V34: =('Portfolio-Level CF'!J10/$O34)*(1-'Portfolio-Level CF'!$AC$52) -> 1.1590794e+08 | W34: =('Portfolio-Level CF'!K10/$O34)*(1-'Portfolio-Level CF'!$AC$52) -> 1.184594e+08 | ... Y34: =('Portfolio-Level CF'!M10/$O34)*(1-'Portfolio-Level CF'!$AC$52) -> 1.2219534e+08 | AA34: =AB32&AB34 -> 2 Riverview NOI | AB34: NOI | AC34: ='Property-Level CF'!CA10 -> 1354228 | AD34: ='Property-Level CF'!CB10 -> 1377820 | AE34: ='Property-Level CF'!CC10 -> 1401741 | AF34: ='Property-Level CF'!CD10 -> 1426308 | AG34: ='Property-Level CF'!CE10 -> 1451191 | AH34: ='Property-Level CF'!CF10 -> 1476575 | AI34: ='Property-Level CF'!CG10 -> 1502242 | AJ34: ='Property-Level CF'!CH10 -> 1528321 | ... AL34: ='Property-Level CF'!CJ10 -> 1584598
O35: 0.055 | P35: =('Portfolio-Level CF'!D10/$O35)*(1-'Portfolio-Level CF'!$AC$52) -> 88918069 | Q35: =('Portfolio-Level CF'!E10/$O35)*(1-'Portfolio-Level CF'!$AC$52) -> 95447161 | R35: =('Portfolio-Level CF'!F10/$O35)*(1-'Portfolio-Level CF'!$AC$52) -> 1.0103685e+08 | S35: =('Portfolio-Level CF'!G10/$O35)*(1-'Portfolio-Level CF'!$AC$52) -> 1.0253494e+08 | T35: =('Portfolio-Level CF'!H10/$O35)*(1-'Portfolio-Level CF'!$AC$52) -> 1.0482215e+08 | U35: =('Portfolio-Level CF'!I10/$O35)*(1-'Portfolio-Level CF'!$AC$52) -> 1.0540491e+08 | V35: =('Portfolio-Level CF'!J10/$O35)*(1-'Portfolio-Level CF'!$AC$52) -> 1.0799991e+08 | W35: =('Portfolio-Level CF'!K10/$O35)*(1-'Portfolio-Level CF'!$AC$52) -> 1.103773e+08 | ... Y35: =('Portfolio-Level CF'!M10/$O35)*(1-'Portfolio-Level CF'!$AC$52) -> 1.1385835e+08 | AA35: =AB32&AB35 -> 2 Riverview NCF before DS | AB35: NCF before DS | AC35: ='Property-Level CF'!CA14 -> 1332627.5 | AD35: ='Property-Level CF'!CB14 -> 1356219.5 | AE35: ='Property-Level CF'!CC14 -> 1380140.5 | AF35: ='Property-Level CF'!CD14 -> 1404707.5 | AG35: ='Property-Level CF'!CE14 -> 1429590.5 | AH35: ='Property-Level CF'!CF14 -> 1454974.5 | AI35: ='Property-Level CF'!CG14 -> 1480641.5 | AJ35: ='Property-Level CF'!CH14 -> 1506720.5 | ... AL35: ='Property-Level CF'!CJ14 -> 1562997.5
B36: Net Cash Flow after Debt Service | D36: =D16-D30 -> 2213642.9 | E36: =E16-E30 -> 2541590.9 | F36: =F16-F30 -> 2853221.9 | G36: =G16-G30 -> 2686619.9 | H36: =H16-H30 -> 3124412.9 | I36: =I16-I30 -> 3157747.9 | J36: =J16-J30 -> 2858394.9 | K36: =K16-K30 -> 3442179.9 | L36: =L16-L30 -> 3035150.9 | M36: =M14-M30 -> 3195014.9 | O36: 0.0575 | P36: =('Portfolio-Level CF'!D10/$O36)*(1-'Portfolio-Level CF'!$AC$52) -> 85052066 | Q36: =('Portfolio-Level CF'!E10/$O36)*(1-'Portfolio-Level CF'!$AC$52) -> 91297284 | R36: =('Portfolio-Level CF'!F10/$O36)*(1-'Portfolio-Level CF'!$AC$52) -> 96643943 | S36: =('Portfolio-Level CF'!G10/$O36)*(1-'Portfolio-Level CF'!$AC$52) -> 98076896 | T36: =('Portfolio-Level CF'!H10/$O36)*(1-'Portfolio-Level CF'!$AC$52) -> 1.0026467e+08 | U36: =('Portfolio-Level CF'!I10/$O36)*(1-'Portfolio-Level CF'!$AC$52) -> 1.0082209e+08 | V36: =('Portfolio-Level CF'!J10/$O36)*(1-'Portfolio-Level CF'!$AC$52) -> 1.0330426e+08 | W36: =('Portfolio-Level CF'!K10/$O36)*(1-'Portfolio-Level CF'!$AC$52) -> 1.0557829e+08 | ... Y36: =('Portfolio-Level CF'!M10/$O36)*(1-'Portfolio-Level CF'!$AC$52) -> 1.0890798e+08 | AB36: DS | AC36: ='Property-Level CF'!CA30 -> 717495.78 | AD36: =AC36 -> 717495.78 | AE36: =AD36 -> 717495.78 | AF36: =AE36 -> 717495.78 | AG36: =AF36 -> 717495.78 | AH36: =AG36 -> 717495.78 | AI36: =AH36 -> 717495.78 | AJ36: =AI36 -> 717495.78 | AK36: =AJ36 -> 717495.78 | AL36: =AK36 -> 717495.78
B37: Sale (Levered) | M37: =M15-M29 -> 53073558 | O37: 0.06 | P37: =('Portfolio-Level CF'!D10/$O37)*(1-'Portfolio-Level CF'!$AC$52) -> 81508230 | Q37: =('Portfolio-Level CF'!E10/$O37)*(1-'Portfolio-Level CF'!$AC$52) -> 87493231 | R37: =('Portfolio-Level CF'!F10/$O37)*(1-'Portfolio-Level CF'!$AC$52) -> 92617112 | S37: =('Portfolio-Level CF'!G10/$O37)*(1-'Portfolio-Level CF'!$AC$52) -> 93990359 | T37: =('Portfolio-Level CF'!H10/$O37)*(1-'Portfolio-Level CF'!$AC$52) -> 96086974 | U37: =('Portfolio-Level CF'!I10/$O37)*(1-'Portfolio-Level CF'!$AC$52) -> 96621167 | V37: =('Portfolio-Level CF'!J10/$O37)*(1-'Portfolio-Level CF'!$AC$52) -> 98999918 | W37: =('Portfolio-Level CF'!K10/$O37)*(1-'Portfolio-Level CF'!$AC$52) -> 1.0117919e+08 | ... Y37: =('Portfolio-Level CF'!M10/$O37)*(1-'Portfolio-Level CF'!$AC$52) -> 1.0437015e+08 | AB37: NCF after DS | AC37: =AC35-AC36 -> 615131.72 | AD37: =AD35-AD36 -> 638723.72 | AE37: =AE35-AE36 -> 662644.72 | AF37: =AF35-AF36 -> 687211.72 | AG37: =AG35-AG36 -> 712094.72 | AH37: =AH35-AH36 -> 737478.72 | AI37: =AI35-AI36 -> 763145.72 | AJ37: =AJ35-AJ36 -> 789224.72 | ... AL37: =AL35-AL36 -> 845501.72
B38: Asset Management Fees | D38: =C39*Summary!C10 -> -90781.633 | E38: =D38 -> -90781.633 | F38: =E38 -> -90781.633 | G38: =F38 -> -90781.633 | H38: =G38 -> -90781.633 | I38: =H38 -> -90781.633 | J38: =I38 -> -90781.633 | K38: =J38 -> -90781.633 | L38: =K38 -> -90781.633 | M38: =L38 -> -90781.633 | AA38: 5 | AB38: 226 White St
B39: Levered Cash Flow | C39: =(C16*(1-Summary!C15)) -> -36312653 | D39: =D36+D37+D38 -> 2122861.3 | E39: =E36+E37+E38 -> 2450809.3 | F39: =F36+F37+F38 -> 2762440.3 | G39: =G36+G37+G38 -> 2595838.3 | H39: =H36+H37+H38 -> 3033631.3 | I39: =I36+I37+I38 -> 3066966.3 | J39: =J36+J37+J38 -> 2767613.3 | K39: =K36+K37+K38 -> 3351398.3 | ... M39: =M36+M37+M38 -> 56177792 | O39: Portfolio Final Year Cash Flow by Cap Rate by Exit Year | AA39: =AB38&AB39 -> 226 White StEGR | AB39: EGR | AC39: ='Property-Level CF'!CZ9 -> 810031 | AD39: ='Property-Level CF'!DA9 -> 827265 | AE39: ='Property-Level CF'!DB9 -> 844869 | AF39: ='Property-Level CF'!DC9 -> 862852 | AG39: ='Property-Level CF'!DD9 -> 881222 | AH39: ='Property-Level CF'!DE9 -> 899987 | AI39: ='Property-Level CF'!DF9 -> 919155 | AJ39: ='Property-Level CF'!DG9 -> 938737 | ... AL39: ='Property-Level CF'!DI9 -> 979173
O40: Cap Rate | P40: =P32 -> Year 1 | Q40: =Q32 -> Year 2 | R40: =R32 -> Year 3 | S40: =S32 -> Year 4 | T40: =T32 -> Year 5 | U40: =U32 -> Year 6 | V40: =V32 -> Year 7 | W40: =W32 -> Year 8 | ... Y40: =Y32 -> Year 10 | AA40: =AB38&AB40 -> 226 White StNOI | AB40: NOI | AC40: ='Property-Level CF'!CZ10 -> 584129 | AD40: ='Property-Level CF'!DA10 -> 595812 | AE40: ='Property-Level CF'!DB10 -> 607728 | AF40: ='Property-Level CF'!DC10 -> 619882 | AG40: ='Property-Level CF'!DD10 -> 632280 | AH40: ='Property-Level CF'!DE10 -> 644926 | AI40: ='Property-Level CF'!DF10 -> 657824 | AJ40: ='Property-Level CF'!DG10 -> 670981 | ... AL40: ='Property-Level CF'!DI10 -> 698088
B41: Cash on Cash Return | D41: =(D14-D30+D38)/-$C$39 -> 0.058460649 | E41: =(E14-E30+E38)/-$C$39 -> 0.067491881 | F41: =(F14-F30+F38)/-$C$39 -> 0.076073766 | G41: =(G14-G30+G38)/-$C$39 -> 0.071485778 | H41: =(H14-H30+H38)/-$C$39 -> 0.083541989 | I41: =(I14-I30+I38)/-$C$39 -> 0.084459989 | J41: =(J14-J30+J38)/-$C$39 -> 0.076216223 | K41: =(K14-K30+K38)/-$C$39 -> 0.09229285 | ... M41: =(M14-M30+M38)/-$C$39 -> 0.08548627 | O41: =O33 -> 0.05 | P41: =((P33-Summary!$C$17)+D39) -> 32494953 | Q41: =((Q33-Summary!$C$17)+E39) -> 40004902 | R41: =((R33-Summary!$C$17)+F39) -> 46465191 | S41: =((S33-Summary!$C$17)+G39) -> 47946484 | T41: =((T33-Summary!$C$17)+H39) -> 50900215 | U41: =((U33-Summary!$C$17)+I39) -> 51574582 | V41: =((V33-Summary!$C$17)+J39) -> 54129731 | W41: =((W33-Summary!$C$17)+K39) -> 57328642 | X41: =((X33-Summary!$C$17)+L39) -> 58302807 | Y41: =((Y33-Summary!$C$17))+$M$39-$M$37 -> 60910631 | AA41: =AB38&AB41 -> 226 White StNCF before DS | AB41: NCF before DS | AC41: ='Property-Level CF'!CZ14 -> 571054 | AD41: ='Property-Level CF'!DA14 -> 582737 | AE41: ='Property-Level CF'!DB14 -> 594653 | AF41: ='Property-Level CF'!DC14 -> 606807 | AG41: ='Property-Level CF'!DD14 -> 619205 | AH41: ='Property-Level CF'!DE14 -> 631851 | AI41: ='Property-Level CF'!DF14 -> 644749 | AJ41: ='Property-Level CF'!DG14 -> 657906 | ... AL41: ='Property-Level CF'!DI14 -> 685013
...

Sheet Property-Level CF
B2: CASH FLOW | O2: Year | P2: =D5 -> Year 1 | Q2: =E5 -> Year 2 | R2: =F5 -> Year 3 | S2: =G5 -> Year 4 | T2: =H5 -> Year 5 | U2: =I5 -> Year 6 | V2: =J5 -> Year 7 | W2: =K5 -> Year 8 | ... Y2: =M5 -> Year 10 | AA2: CASH FLOW | AN2: Year | AO2: ='Property-Level CF'!AC5 -> Year 1 | AP2: ='Property-Level CF'!AD5 -> Year 2 | AQ2: ='Property-Level CF'!AE5 -> Year 3 | AR2: ='Property-Level CF'!AF5 -> Year 4 | AS2: ='Property-Level CF'!AG5 -> Year 5 | AT2: ='Property-Level CF'!AH5 -> Year 6 | AU2: ='Property-Level CF'!AI5 -> Year 7 | AV2: ='Property-Level CF'!AJ5 -> Year 8 | ... AX2: ='Property-Level CF'!AL5 -> Year 10 | AZ2: CASH FLOW | BM2: Year | BN2: ='Property-Level CF'!BB5 -> Year 1 | BO2: ='Property-Level CF'!BC5 -> Year 2 | BP2: ='Property-Level CF'!BD5 -> Year 3 | BQ2: ='Property-Level CF'!BE5 -> Year 4 | BR2: ='Property-Level CF'!BF5 -> Year 5 | BS2: ='Property-Level CF'!BG5 -> Year 6 | BT2: ='Property-Level CF'!BH5 -> Year 7 | BU2: ='Property-Level CF'!BI5 -> Year 8 | ... BW2: ='Property-Level CF'!BK5 -> Year 10 | BY2: CASH FLOW | CL2: Year | CM2: ='Property-Level CF'!CA5 -> Year 1 | CN2: ='Property-Level CF'!CB5 -> Year 2 | CO2: ='Property-Level CF'!CC5 -> Year 3 | CP2: ='Property-Level CF'!CD5 -> Year 4 | CQ2: ='Property-Level CF'!CE5 -> Year 5 | CR2: ='Property-Level CF'!CF5 -> Year 6 | CS2: ='Property-Level CF'!CG5 -> Year 7 | CT2: ='Property-Level CF'!CH5 -> Year 8 | ... CV2: ='Property-Level CF'!CJ5 -> Year 10 | CX2: CASH FLOW | DK2: Year | DL2: ='Property-Level CF'!CZ5 -> Year 1 | DM2: ='Property-Level CF'!DA5 -> Year 2 | DN2: ='Property-Level CF'!DB5 -> Year 3 | DO2: ='Property-Level CF'!DC5 -> Year 4 | DP2: ='Property-Level CF'!DD5 -> Year 5 | DQ2: ='Property-Level CF'!DE5 -> Year 6 | DR2: ='Property-Level CF'!DF5 -> Year 7 | DS2: ='Property-Level CF'!DG5 -> Year 8 | ... DU2: ='Property-Level CF'!DI5 -> Year 10 | DW2: CASH FLOW | EJ2: Year | EK2: ='Property-Level CF'!DY5 -> Year 1 | EL2: ='Property-Level CF'!DZ5 -> Year 2 | EM2: ='Property-Level CF'!EA5 -> Year 3 | EN2: ='Property-Level CF'!EB5 -> Year 4 | EO2: ='Property-Level CF'!EC5 -> Year 5 | EP2: ='Property-Level CF'!ED5 -> Year 6 | EQ2: ='Property-Level CF'!EE5 -> Year 7 | ER2: ='Property-Level CF'!EF5 -> Year 8 | ... ET2: ='Property-Level CF'!EH5 -> Year 10
B3: =Summary!E4 -> 131 Kent Road, New Milford, CT 06776 | O3: Unlevered IRR | P3: =IRR(P4:P15) -> 0.018207065 | Q3: =IRR(Q4:Q15) -> 0.041901141 | R3: =IRR(R4:R15) -> 0.049895376 | S3: =IRR(S4:S15) -> 0.045662949 | T3: =IRR(T4:T15) -> 0.057865901 | U3: =IRR(U4:U15) -> 0.048907337 | V3: =IRR(V4:V15) -> 0.048552772 | W3: =IRR(W4:W15) -> 0.055276831 | ... Y3: =IRR(Y4:Y15) -> 0.056123945 | AA3: =Summary!E5 -> 164 Mount Pleasant Road, Newtown, CT 06470 | AN3: Unlevered IRR | AO3: =IRR(AO4:AO15) -> -0.0012527016 | AP3: =IRR(AP4:AP15) -> 0.0079366159 | AQ3: =IRR(AQ4:AQ15) -> 0.11035437 | AR3: =IRR(AR4:AR15) -> 0.10336455 | AS3: =IRR(AS4:AS15) -> 0.098897827 | AT3: =IRR(AT4:AT15) -> 0.093966435 | AU3: =IRR(AU4:AU15) -> 0.090460677 | AV3: =IRR(AV4:AV15) -> 0.087849783 | ... AX3: =IRR(AX4:AX15) -> 0.081037425 | AZ3: =Summary!E6 -> 170 Mount Pleasant Road, Newtown, CT 06470 | BM3: Unlevered IRR | BN3: =IRR(BN4:BN15) -> 0.0058039353 | BO3: =IRR(BO4:BO15) -> 0.061650282 | BP3: =IRR(BP4:BP15) -> 0.09312356 | BQ3: =IRR(BQ4:BQ15) -> 0.085985009 | BR3: =IRR(BR4:BR15) -> 0.081719594 | BS3: =IRR(BS4:BS15) -> 0.078954769 | BT3: =IRR(BT4:BT15) -> 0.084043199 | BU3: =IRR(BU4:BU15) -> 0.08297021 | ... BW3: =IRR(BW4:BW15) -> 0.079510418 | BY3: =Summary!E7 -> 2 Riverview Drive, Danbury, CT 06810 | CL3: Unlevered IRR | CM3: =IRR(CM4:CM15) -> 0.01114134 | CN3: =IRR(CN4:CN15) -> 0.034896017 | CO3: =IRR(CO4:CO15) -> 0.046020665 | CP3: =IRR(CP4:CP15) -> 0.051663947 | CQ3: =IRR(CQ4:CQ15) -> 0.055046562 | CR3: =IRR(CR4:CR15) -> 0.057312169 | CS3: =IRR(CS4:CS15) -> 0.058917249 | CT3: =IRR(CT4:CT15) -> 0.060118142 | ... CV3: =IRR(CV4:CV15) -> 0.061945 | CX3: =Summary!E8 -> 226 White Street, Danbury, CT 06810 | DK3: Unlevered IRR | DL3: =IRR(DL4:DL15) -> 0.011756166 | DM3: =IRR(DM4:DM15) -> 0.036804407 | DN3: =IRR(DN4:DN15) -> 0.048400461 | DO3: =IRR(DO4:DO15) -> 0.054245238 | DP3: =IRR(DP4:DP15) -> 0.057766297 | DQ3: =IRR(DQ4:DQ15) -> 0.060118578 | DR3: =IRR(DR4:DR15) -> 0.061800261 | DS3: =IRR(DS4:DS15) -> 0.063061998 | ... DU3: =IRR(DU4:DU15) -> 0.064826948 | DW3: =Summary!E9 -> 40 Old Ridgebury Road, Danbury, CT 06810 | EJ3: Unlevered IRR | EK3: =IRR(EK4:EK15) -> 0.0091266662 | EL3: =IRR(EL4:EL15) -> 0.034165979 | EM3: =IRR(EM4:EM15) -> 0.045690436 | EN3: =IRR(EN4:EN15) -> 0.051532587 | EO3: =IRR(EO4:EO15) -> 0.055051513 | EP3: =IRR(EP4:EP15) -> 0.057406682 | EQ3: =IRR(EQ4:EQ15) -> 0.059072596 | ER3: =IRR(ER4:ER15) -> 0.060346407 | ... ET3: =IRR(ET4:ET15) -> 0.062094976
O4: 0 | P4: ='Property-Level CF'!C16 -> -13422181 | Q4: =P4 -> -13422181 | R4: =Q4 -> -13422181 | S4: =R4 -> -13422181 | T4: =S4 -> -13422181 | U4: =T4 -> -13422181 | V4: =U4 -> -13422181 | W4: =V4 -> -13422181 | X4: =W4 -> -13422181 | Y4: =X4 -> -13422181 | AN4: 0 | AO4: ='Property-Level CF'!AB16 -> -10961842 | AP4: =AO4 -> -10961842 | AQ4: =AP4 -> -10961842 | AR4: =AQ4 -> -10961842 | AS4: =AR4 -> -10961842 | AT4: =AS4 -> -10961842 | AU4: =AT4 -> -10961842 | AV4: =AU4 -> -10961842 | AW4: =AV4 -> -10961842 | AX4: =AW4 -> -10961842 | BM4: 0 | BN4: ='Property-Level CF'!BA16 -> -14068705 | BO4: =BN4 -> -14068705 | BP4: =BO4 -> -14068705 | BQ4: =BP4 -> -14068705 | BR4: =BQ4 -> -14068705 | BS4: =BR4 -> -14068705 | BT4: =BS4 -> -14068705 | BU4: =BT4 -> -14068705 | BV4: =BU4 -> -14068705 | BW4: =BV4 -> -14068705 | CL4: 0 | CM4: ='Property-Level CF'!BZ16 -> -26845115 | CN4: =CM4 -> -26845115 | CO4: =CN4 -> -26845115 | CP4: =CO4 -> -26845115 | CQ4: =CP4 -> -26845115 | CR4: =CQ4 -> -26845115 | CS4: =CR4 -> -26845115 | CT4: =CS4 -> -26845115 | CU4: =CT4 -> -26845115 | CV4: =CU4 -> -26845115 | DK4: 0 | DL4: ='Property-Level CF'!CY16 -> -11362865 | DM4: =DL4 -> -11362865 | DN4: =DM4 -> -11362865 | DO4: =DN4 -> -11362865 | DP4: =DO4 -> -11362865 | DQ4: =DP4 -> -11362865 | DR4: =DQ4 -> -11362865 | DS4: =DR4 -> -11362865 | DT4: =DS4 -> -11362865 | DU4: =DT4 -> -11362865 | EJ4: 0 | EK4: ='Property-Level CF'!DX16 -> -27089729 | EL4: =EK4 -> -27089729 | EM4: =EL4 -> -27089729 | EN4: =EM4 -> -27089729 | EO4: =EN4 -> -27089729 | EP4: =EO4 -> -27089729 | EQ4: =EP4 -> -27089729 | ER4: =EQ4 -> -27089729 | ES4: =ER4 -> -27089729 | ET4: =ES4 -> -27089729
C5: ='Portfolio-Level CF'!C5 -> Year 0 | D5: ='Portfolio-Level CF'!D5 -> Year 1 | E5: ='Portfolio-Level CF'!E5 -> Year 2 | F5: ='Portfolio-Level CF'!F5 -> Year 3 | G5: ='Portfolio-Level CF'!G5 -> Year 4 | H5: ='Portfolio-Level CF'!H5 -> Year 5 | I5: ='Portfolio-Level CF'!I5 -> Year 6 | J5: ='Portfolio-Level CF'!J5 -> Year 7 | ... M5: ='Portfolio-Level CF'!M5 -> Year 10 | O5: =O4+1 -> 1 | P5: ='Property-Level CF'!D23+'Property-Level CF'!D14 -> 13666560 | Q5: ='Property-Level CF'!D14 -> 761132.5 | R5: =Q5 -> 761132.5 | S5: =R5 -> 761132.5 | T5: =S5 -> 761132.5 | U5: =T5 -> 761132.5 | V5: =U5 -> 761132.5 | W5: =V5 -> 761132.5 | X5: =W5 -> 761132.5 | Y5: =X5 -> 761132.5 | AB5: ='Property-Level CF'!C5 -> Year 0 | AC5: ='Property-Level CF'!D5 -> Year 1 | AD5: ='Property-Level CF'!E5 -> Year 2 | AE5: ='Property-Level CF'!F5 -> Year 3 | AF5: ='Property-Level CF'!G5 -> Year 4 | AG5: ='Property-Level CF'!H5 -> Year 5 | AH5: ='Property-Level CF'!I5 -> Year 6 | AI5: ='Property-Level CF'!J5 -> Year 7 | ... AL5: ='Property-Level CF'!M5 -> Year 10 | AN5: =AN4+1 -> 1 | AO5: ='Property-Level CF'!AC23+'Property-Level CF'!AC14 -> 10948110 | AP5: ='Property-Level CF'!AC14 -> 408299 | AQ5: =AP5 -> 408299 | AR5: =AQ5 -> 408299 | AS5: =AR5 -> 408299 | AT5: =AS5 -> 408299 | AU5: =AT5 -> 408299 | AV5: =AU5 -> 408299 | AW5: =AV5 -> 408299 | AX5: =AW5 -> 408299 | BA5: ='Property-Level CF'!AB5 -> Year 0 | BB5: ='Property-Level CF'!AC5 -> Year 1 | BC5: ='Property-Level CF'!AD5 -> Year 2 | BD5: ='Property-Level CF'!AE5 -> Year 3 | BE5: ='Property-Level CF'!AF5 -> Year 4 | BF5: ='Property-Level CF'!AG5 -> Year 5 | BG5: ='Property-Level CF'!AH5 -> Year 6 | BH5: ='Property-Level CF'!AI5 -> Year 7 | ... BK5: ='Property-Level CF'!AL5 -> Year 10 | BM5: =BM4+1 -> 1 | BN5: ='Property-Level CF'!BB23+'Property-Level CF'!BB14 -> 14150359 | BO5: ='Property-Level CF'!BB14 -> 623299 | BP5: =BO5 -> 623299 | BQ5: =BP5 -> 623299 | BR5: =BQ5 -> 623299 | BS5: =BR5 -> 623299 | BT5: =BS5 -> 623299 | BU5: =BT5 -> 623299 | BV5: =BU5 -> 623299 | BW5: =BV5 -> 623299 | BZ5: ='Portfolio-Level CF'!C5 -> Year 0 | CA5: ='Portfolio-Level CF'!D5 -> Year 1 | CB5: ='Portfolio-Level CF'!E5 -> Year 2 | CC5: ='Portfolio-Level CF'!F5 -> Year 3 | CD5: ='Portfolio-Level CF'!G5 -> Year 4 | CE5: ='Portfolio-Level CF'!H5 -> Year 5 | CF5: ='Portfolio-Level CF'!I5 -> Year 6 | CG5: ='Portfolio-Level CF'!J5 -> Year 7 | ... CJ5: ='Portfolio-Level CF'!M5 -> Year 10 | CL5: =CL4+1 -> 1 | CM5: ='Property-Level CF'!CA23+'Property-Level CF'!CA14 -> 27144206 | CN5: ='Property-Level CF'!CA14 -> 1332627.5 | CO5: =CN5 -> 1332627.5 | CP5: =CO5 -> 1332627.5 | CQ5: =CP5 -> 1332627.5 | CR5: =CQ5 -> 1332627.5 | CS5: =CR5 -> 1332627.5 | CT5: =CS5 -> 1332627.5 | CU5: =CT5 -> 1332627.5 | CV5: =CU5 -> 1332627.5 | CY5: ='Property-Level CF'!DX5 -> Year 0 | CZ5: ='Property-Level CF'!DY5 -> Year 1 | DA5: ='Property-Level CF'!DZ5 -> Year 2 | DB5: ='Property-Level CF'!EA5 -> Year 3 | DC5: ='Property-Level CF'!EB5 -> Year 4 | DD5: ='Property-Level CF'!EC5 -> Year 5 | DE5: ='Property-Level CF'!ED5 -> Year 6 | DF5: ='Property-Level CF'!EE5 -> Year 7 | ... DI5: ='Property-Level CF'!EH5 -> Year 10 | DK5: =DK4+1 -> 1 | DL5: ='Property-Level CF'!CZ23+'Property-Level CF'!CZ14 -> 11496448 | DM5: ='Property-Level CF'!CZ14 -> 571054 | DN5: =DM5 -> 571054 | DO5: =DN5 -> 571054 | DP5: =DO5 -> 571054 | DQ5: =DP5 -> 571054 | DR5: =DQ5 -> 571054 | DS5: =DR5 -> 571054 | DT5: =DS5 -> 571054 | DU5: =DT5 -> 571054 | DX5: ='Property-Level CF'!BZ5 -> Year 0 | DY5: ='Property-Level CF'!CA5 -> Year 1 | DZ5: ='Property-Level CF'!CB5 -> Year 2 | EA5: ='Property-Level CF'!CC5 -> Year 3 | EB5: ='Property-Level CF'!CD5 -> Year 4 | EC5: ='Property-Level CF'!CE5 -> Year 5 | ED5: ='Property-Level CF'!CF5 -> Year 6 | EE5: ='Property-Level CF'!CG5 -> Year 7 | ... EH5: ='Property-Level CF'!CJ5 -> Year 10 | EJ5: =EJ4+1 -> 1 | EK5: ='Property-Level CF'!DY23+'Property-Level CF'!DY14 -> 27336968 | EL5: ='Property-Level CF'!DY14 -> 1290193.5 | EM5: =EL5 -> 1290193.5 | EN5: =EM5 -> 1290193.5 | EO5: =EN5 -> 1290193.5 | EP5: =EO5 -> 1290193.5 | EQ5: =EP5 -> 1290193.5 | ER5: =EQ5 -> 1290193.5 | ES5: =ER5 -> 1290193.5 | ET5: =ES5 -> 1290193.5
